Workbook
Name PEOPLE: 'Cài đặt'!$D$5:$D$44
Name HOLI: 'Cài đặt'!$H$5:$H$64
Name SK_A: 'Sự kiện'!$A$5:$A$304
Name SK_B: 'Sự kiện'!$B$5:$B$304
Name SK_C: 'Sự kiện'!$C$5:$C$304
Name SK_D: 'Sự kiện'!$D$5:$D$304
Name SK_L: 'Sự kiện'!$L$5:$L$304

Sheet Dashboard
A1: DASHBOARD TIẾN ĐỘ SỰ KIỆN
A2: ="Cập nhật đến "&TEXT(TODAY(),"dd/mm/yyyy")&" · chỉ tính sự kiện đang theo dõi (Sự kiện ▸ Theo dõi = Có)"
A4: Sự kiện đang theo dõi | B4: Việc đang mở | D4: QUÁ HẠN | F4: Đến hạn ≤ 3 ngày | H4: Chưa giao người | J4: % việc đã xong
A5: =COUNT('Sự kiện'!$T$5:$T$304) | B5: =COUNTIFS('Giao việc'!$R$5:$R$3004,"Có",'Giao việc'!$I$5:$I$3004,"<>Xong",'Giao việc'!$I$5:$I$3004,"<>Bỏ qua",'Giao việc'!$E$5:$E$3004,"<>") | D5: =COUNTIFS('Giao việc'!$R$5:$R$3004,"Có",'Giao việc'!$L$5:$L$3004,"*QUÁ HẠN*") | F5: =COUNTIFS('Giao việc'!$R$5:$R$3004,"Có",'Giao việc'!$L$5:$L$3004,"*Đến hạn*") | H5: =COUNTIFS('Giao việc'!$R$5:$R$3004,"Có",'Giao việc'!$L$5:$L$3004,"CHƯA GIAO*") | J5: =IFERROR(COUNTIFS('Giao việc'!$R$5:$R$3004,"Có",'Giao việc'!$I$5:$I$3004,"Xong")/COUNTIFS('Giao việc'!$R$5:$R$3004,"Có",'Giao việc'!$I$5:$I$3004,"<>Bỏ qua",'Giao việc'!$E$5:$E$3004,"<>"),0)
A7: TIẾN ĐỘ TỪNG SỰ KIỆN (sắp tới trước)
A8: Sự kiện | B8: Ngày D | C8: Thời gian | D8: Owner | E8: Xong | F8: Còn lại | G8: Quá hạn | H8: Chưa giao | I8: % | J8: Tiến độ
A9: =IF(IFERROR(MATCH(SMALL('Sự kiện'!$T$5:$T$304,1),'Sự kiện'!$T$5:$T$304,0),0)=0,"",INDEX('Sự kiện'!$B$5:$B$304,IFERROR(MATCH(SMALL('Sự kiện'!$T$5:$T$304,1),'Sự kiện'!$T$5:$T$304,0),0))&"") | B9: =IF(IFERROR(MATCH(SMALL('Sự kiện'!$T$5:$T$304,1),'Sự kiện'!$T$5:$T$304,0),0)=0,"",INDEX('Sự kiện'!$C$5:$C$304,IFERROR(MATCH(SMALL('Sự kiện'!$T$5:$T$304,1),'Sự kiện'!$T$5:$T$304,0),0))) | C9: =IF(IFERROR(MATCH(SMALL('Sự kiện'!$T$5:$T$304,1),'Sự kiện'!$T$5:$T$304,0),0)=0,"",INDEX('Sự kiện'!$S$5:$S$304,IFERROR(MATCH(SMALL('Sự kiện'!$T$5:$T$304,1),'Sự kiện'!$T$5:$T$304,0),0))&"") | D9: =IF(IFERROR(MATCH(SMALL('Sự kiện'!$T$5:$T$304,1),'Sự kiện'!$T$5:$T$304,0),0)=0,"",INDEX('Sự kiện'!$K$5:$K$304,IFERROR(MATCH(SMALL('Sự kiện'!$T$5:$T$304,1),'Sự kiện'!$T$5:$T$304,0),0))&"") | E9: =IF(IFERROR(MATCH(SMALL('Sự kiện'!$T$5:$T$304,1),'Sự kiện'!$T$5:$T$304,0),0)=0,"",INDEX('Sự kiện'!$N$5:$N$304,IFERROR(MATCH(SMALL('Sự kiện'!$T$5:$T$304,1),'Sự kiện'!$T$5:$T$304,0),0))) | F9: =IF(A9="","",N(INDEX('Sự kiện'!$M$5:$M$304,IFERROR(MATCH(SMALL('Sự kiện'!$T$5:$T$304,1),'Sự kiện'!$T$5:$T$304,0),0)))-N(E9)-N(G9)) | G9: =IF(IFERROR(MATCH(SMALL('Sự kiện'!$T$5:$T$304,1),'Sự kiện'!$T$5:$T$304,0),0)=0,"",INDEX('Sự kiện'!$O$5:$O$304,IFERROR(MATCH(SMALL('Sự kiện'!$T$5:$T$304,1),'Sự kiện'!$T$5:$T$304,0),0))) | H9: =IF(IFERROR(MATCH(SMALL('Sự kiện'!$T$5:$T$304,1),'Sự kiện'!$T$5:$T$304,0),0)=0,"",INDEX('Sự kiện'!$P$5:$P$304,IFERROR(MATCH(SMALL('Sự kiện'!$T$5:$T$304,1),'Sự kiện'!$T$5:$T$304,0),0))) | I9: =IF(IFERROR(MATCH(SMALL('Sự kiện'!$T$5:$T$304,1),'Sự kiện'!$T$5:$T$304,0),0)=0,"",INDEX('Sự kiện'!$Q$5:$Q$304,IFERROR(MATCH(SMALL('Sự kiện'!$T$5:$T$304,1),'Sự kiện'!$T$5:$T$304,0),0))) | J9: =IF(IFERROR(MATCH(SMALL('Sự kiện'!$T$5:$T$304,1),'Sự kiện'!$T$5:$T$304,0),0)=0,"",INDEX('Sự kiện'!$R$5:$R$304,IFERROR(MATCH(SMALL('Sự kiện'!$T$5:$T$304,1),'Sự kiện'!$T$5:$T$304,0),0))&"")
A10: =IF(IFERROR(MATCH(SMALL('Sự kiện'!$T$5:$T$304,2),'Sự kiện'!$T$5:$T$304,0),0)=0,"",INDEX('Sự kiện'!$B$5:$B$304,IFERROR(MATCH(SMALL('Sự kiện'!$T$5:$T$304,2),'Sự kiện'!$T$5:$T$304,0),0))&"") | B10: =IF(IFERROR(MATCH(SMALL('Sự kiện'!$T$5:$T$304,2),'Sự kiện'!$T$5:$T$304,0),0)=0,"",INDEX('Sự kiện'!$C$5:$C$304,IFERROR(MATCH(SMALL('Sự kiện'!$T$5:$T$304,2),'Sự kiện'!$T$5:$T$304,0),0))) | C10: =IF(IFERROR(MATCH(SMALL('Sự kiện'!$T$5:$T$304,2),'Sự kiện'!$T$5:$T$304,0),0)=0,"",INDEX('Sự kiện'!$S$5:$S$304,IFERROR(MATCH(SMALL('Sự kiện'!$T$5:$T$304,2),'Sự kiện'!$T$5:$T$304,0),0))&"") | D10: =IF(IFERROR(MATCH(SMALL('Sự kiện'!$T$5:$T$304,2),'Sự kiện'!$T$5:$T$304,0),0)=0,"",INDEX('Sự kiện'!$K$5:$K$304,IFERROR(MATCH(SMALL('Sự kiện'!$T$5:$T$304,2),'Sự kiện'!$T$5:$T$304,0),0))&"") | E10: =IF(IFERROR(MATCH(SMALL('Sự kiện'!$T$5:$T$304,2),'Sự kiện'!$T$5:$T$304,0),0)=0,"",INDEX('Sự kiện'!$N$5:$N$304,IFERROR(MATCH(SMALL('Sự kiện'!$T$5:$T$304,2),'Sự kiện'!$T$5:$T$304,0),0))) | F10: =IF(A10="","",N(INDEX('Sự kiện'!$M$5:$M$304,IFERROR(MATCH(SMALL('Sự kiện'!$T$5:$T$304,2),'Sự kiện'!$T$5:$T$304,0),0)))-N(E10)-N(G10)) | G10: =IF(IFERROR(MATCH(SMALL('Sự kiện'!$T$5:$T$304,2),'Sự kiện'!$T$5:$T$304,0),0)=0,"",INDEX('Sự kiện'!$O$5:$O$304,IFERROR(MATCH(SMALL('Sự kiện'!$T$5:$T$304,2),'Sự kiện'!$T$5:$T$304,0),0))) | H10: =IF(IFERROR(MATCH(SMALL('Sự kiện'!$T$5:$T$304,2),'Sự kiện'!$T$5:$T$304,0),0)=0,"",INDEX('Sự kiện'!$P$5:$P$304,IFERROR(MATCH(SMALL('Sự kiện'!$T$5:$T$304,2),'Sự kiện'!$T$5:$T$304,0),0))) | I10: =IF(IFERROR(MATCH(SMALL('Sự kiện'!$T$5:$T$304,2),'Sự kiện'!$T$5:$T$304,0),0)=0,"",INDEX('Sự kiện'!$Q$5:$Q$304,IFERROR(MATCH(SMALL('Sự kiện'!$T$5:$T$304,2),'Sự kiện'!$T$5:$T$304,0),0))) | J10: =IF(IFERROR(MATCH(SMALL('Sự kiện'!$T$5:$T$304,2),'Sự kiện'!$T$5:$T$304,0),0)=0,"",INDEX('Sự kiện'!$R$5:$R$304,IFERROR(MATCH(SMALL('Sự kiện'!$T$5:$T$304,2),'Sự kiện'!$T$5:$T$304,0),0))&"")
A11: =IF(IFERROR(MATCH(SMALL('Sự kiện'!$T$5:$T$304,3),'Sự kiện'!$T$5:$T$304,0),0)=0,"",INDEX('Sự kiện'!$B$5:$B$304,IFERROR(MATCH(SMALL('Sự kiện'!$T$5:$T$304,3),'Sự kiện'!$T$5:$T$304,0),0))&"") | B11: =IF(IFERROR(MATCH(SMALL('Sự kiện'!$T$5:$T$304,3),'Sự kiện'!$T$5:$T$304,0),0)=0,"",INDEX('Sự kiện'!$C$5:$C$304,IFERROR(MATCH(SMALL('Sự kiện'!$T$5:$T$304,3),'Sự kiện'!$T$5:$T$304,0),0))) | C11: =IF(IFERROR(MATCH(SMALL('Sự kiện'!$T$5:$T$304,3),'Sự kiện'!$T$5:$T$304,0),0)=0,"",INDEX('Sự kiện'!$S$5:$S$304,IFERROR(MATCH(SMALL('Sự kiện'!$T$5:$T$304,3),'Sự kiện'!$T$5:$T$304,0),0))&"") | D11: =IF(IFERROR(MATCH(SMALL('Sự kiện'!$T$5:$T$304,3),'Sự kiện'!$T$5:$T$304,0),0)=0,"",INDEX('Sự kiện'!$K$5:$K$304,IFERROR(MATCH(SMALL('Sự kiện'!$T$5:$T$304,3),'Sự kiện'!$T$5:$T$304,0),0))&"") | E11: =IF(IFERROR(MATCH(SMALL('Sự kiện'!$T$5:$T$304,3),'Sự kiện'!$T$5:$T$304,0),0)=0,"",INDEX('Sự kiện'!$N$5:$N$304,IFERROR(MATCH(SMALL('Sự kiện'!$T$5:$T$304,3),'Sự kiện'!$T$5:$T$304,0),0))) | F11: =IF(A11="","",N(INDEX('Sự kiện'!$M$5:$M$304,IFERROR(MATCH(SMALL('Sự kiện'!$T$5:$T$304,3),'Sự kiện'!$T$5:$T$304,0),0)))-N(E11)-N(G11)) | G11: =IF(IFERROR(MATCH(SMALL('Sự kiện'!$T$5:$T$304,3),'Sự kiện'!$T$5:$T$304,0),0)=0,"",INDEX('Sự kiện'!$O$5:$O$304,IFERROR(MATCH(SMALL('Sự kiện'!$T$5:$T$304,3),'Sự kiện'!$T$5:$T$304,0),0))) | H11: =IF(IFERROR(MATCH(SMALL('Sự kiện'!$T$5:$T$304,3),'Sự kiện'!$T$5:$T$304,0),0)=0,"",INDEX('Sự kiện'!$P$5:$P$304,IFERROR(MATCH(SMALL('Sự kiện'!$T$5:$T$304,3),'Sự kiện'!$T$5:$T$304,0),0))) | I11: =IF(IFERROR(MATCH(SMALL('Sự kiện'!$T$5:$T$304,3),'Sự kiện'!$T$5:$T$304,0),0)=0,"",INDEX('Sự kiện'!$Q$5:$Q$304,IFERROR(MATCH(SMALL('Sự kiện'!$T$5:$T$304,3),'Sự kiện'!$T$5:$T$304,0),0))) | J11: =IF(IFERROR(MATCH(SMALL('Sự kiện'!$T$5:$T$304,3),'Sự kiện'!$T$5:$T$304,0),0)=0,"",INDEX('Sự kiện'!$R$5:$R$304,IFERROR(MATCH(SMALL('Sự kiện'!$T$5:$T$304,3),'Sự kiện'!$T$5:$T$304,0),0))&"")
A12: =IF(IFERROR(MATCH(SMALL('Sự kiện'!$T$5:$T$304,4),'Sự kiện'!$T$5:$T$304,0),0)=0,"",INDEX('Sự kiện'!$B$5:$B$304,IFERROR(MATCH(SMALL('Sự kiện'!$T$5:$T$304,4),'Sự kiện'!$T$5:$T$304,0),0))&"") | B12: =IF(IFERROR(MATCH(SMALL('Sự kiện'!$T$5:$T$304,4),'Sự kiện'!$T$5:$T$304,0),0)=0,"",INDEX('Sự kiện'!$C$5:$C$304,IFERROR(MATCH(SMALL('Sự kiện'!$T$5:$T$304,4),'Sự kiện'!$T$5:$T$304,0),0))) | C12: =IF(IFERROR(MATCH(SMALL('Sự kiện'!$T$5:$T$304,4),'Sự kiện'!$T$5:$T$304,0),0)=0,"",INDEX('Sự kiện'!$S$5:$S$304,IFERROR(MATCH(SMALL('Sự kiện'!$T$5:$T$304,4),'Sự kiện'!$T$5:$T$304,0),0))&"") | D12: =IF(IFERROR(MATCH(SMALL('Sự kiện'!$T$5:$T$304,4),'Sự kiện'!$T$5:$T$304,0),0)=0,"",INDEX('Sự kiện'!$K$5:$K$304,IFERROR(MATCH(SMALL('Sự kiện'!$T$5:$T$304,4),'Sự kiện'!$T$5:$T$304,0),0))&"") | E12: =IF(IFERROR(MATCH(SMALL('Sự kiện'!$T$5:$T$304,4),'Sự kiện'!$T$5:$T$304,0),0)=0,"",INDEX('Sự kiện'!$N$5:$N$304,IFERROR(MATCH(SMALL('Sự kiện'!$T$5:$T$304,4),'Sự kiện'!$T$5:$T$304,0),0))) | F12: =IF(A12="","",N(INDEX('Sự kiện'!$M$5:$M$304,IFERROR(MATCH(SMALL('Sự kiện'!$T$5:$T$304,4),'Sự kiện'!$T$5:$T$304,0),0)))-N(E12)-N(G12)) | G12: =IF(IFERROR(MATCH(SMALL('Sự kiện'!$T$5:$T$304,4),'Sự kiện'!$T$5:$T$304,0),0)=0,"",INDEX('Sự kiện'!$O$5:$O$304,IFERROR(MATCH(SMALL('Sự kiện'!$T$5:$T$304,4),'Sự kiện'!$T$5:$T$304,0),0))) | H12: =IF(IFERROR(MATCH(SMALL('Sự kiện'!$T$5:$T$304,4),'Sự kiện'!$T$5:$T$304,0),0)=0,"",INDEX('Sự kiện'!$P$5:$P$304,IFERROR(MATCH(SMALL('Sự kiện'!$T$5:$T$304,4),'Sự kiện'!$T$5:$T$304,0),0))) | I12: =IF(IFERROR(MATCH(SMALL('Sự kiện'!$T$5:$T$304,4),'Sự kiện'!$T$5:$T$304,0),0)=0,"",INDEX('Sự kiện'!$Q$5:$Q$304,IFERROR(MATCH(SMALL('Sự kiện'!$T$5:$T$304,4),'Sự kiện'!$T$5:$T$304,0),0))) | J12: =IF(IFERROR(MATCH(SMALL('Sự kiện'!$T$5:$T$304,4),'Sự kiện'!$T$5:$T$304,0),0)=0,"",INDEX('Sự kiện'!$R$5:$R$304,IFERROR(MATCH(SMALL('Sự kiện'!$T$5:$T$304,4),'Sự kiện'!$T$5:$T$304,0),0))&"")
A13: =IF(IFERROR(MATCH(SMALL('Sự kiện'!$T$5:$T$304,5),'Sự kiện'!$T$5:$T$304,0),0)=0,"",INDEX('Sự kiện'!$B$5:$B$304,IFERROR(MATCH(SMALL('Sự kiện'!$T$5:$T$304,5),'Sự kiện'!$T$5:$T$304,0),0))&"") | B13: =IF(IFERROR(MATCH(SMALL('Sự kiện'!$T$5:$T$304,5),'Sự kiện'!$T$5:$T$304,0),0)=0,"",INDEX('Sự kiện'!$C$5:$C$304,IFERROR(MATCH(SMALL('Sự kiện'!$T$5:$T$304,5),'Sự kiện'!$T$5:$T$304,0),0))) | C13: =IF(IFERROR(MATCH(SMALL('Sự kiện'!$T$5:$T$304,5),'Sự kiện'!$T$5:$T$304,0),0)=0,"",INDEX('Sự kiện'!$S$5:$S$304,IFERROR(MATCH(SMALL('Sự kiện'!$T$5:$T$304,5),'Sự kiện'!$T$5:$T$304,0),0))&"") | D13: =IF(IFERROR(MATCH(SMALL('Sự kiện'!$T$5:$T$304,5),'Sự kiện'!$T$5:$T$304,0),0)=0,"",INDEX('Sự kiện'!$K$5:$K$304,IFERROR(MATCH(SMALL('Sự kiện'!$T$5:$T$304,5),'Sự kiện'!$T$5:$T$304,0),0))&"") | E13: =IF(IFERROR(MATCH(SMALL('Sự kiện'!$T$5:$T$304,5),'Sự kiện'!$T$5:$T$304,0),0)=0,"",INDEX('Sự kiện'!$N$5:$N$304,IFERROR(MATCH(SMALL('Sự kiện'!$T$5:$T$304,5),'Sự kiện'!$T$5:$T$304,0),0))) | F13: =IF(A13="","",N(INDEX('Sự kiện'!$M$5:$M$304,IFERROR(MATCH(SMALL('Sự kiện'!$T$5:$T$304,5),'Sự kiện'!$T$5:$T$304,0),0)))-N(E13)-N(G13)) | G13: =IF(IFERROR(MATCH(SMALL('Sự kiện'!$T$5:$T$304,5),'Sự kiện'!$T$5:$T$304,0),0)=0,"",INDEX('Sự kiện'!$O$5:$O$304,IFERROR(MATCH(SMALL('Sự kiện'!$T$5:$T$304,5),'Sự kiện'!$T$5:$T$304,0),0))) | H13: =IF(IFERROR(MATCH(SMALL('Sự kiện'!$T$5:$T$304,5),'Sự kiện'!$T$5:$T$304,0),0)=0,"",INDEX('Sự kiện'!$P$5:$P$304,IFERROR(MATCH(SMALL('Sự kiện'!$T$5:$T$304,5),'Sự kiện'!$T$5:$T$304,0),0))) | I13: =IF(IFERROR(MATCH(SMALL('Sự kiện'!$T$5:$T$304,5),'Sự kiện'!$T$5:$T$304,0),0)=0,"",INDEX('Sự kiện'!$Q$5:$Q$304,IFERROR(MATCH(SMALL('Sự kiện'!$T$5:$T$304,5),'Sự kiện'!$T$5:$T$304,0),0))) | J13: =IF(IFERROR(MATCH(SMALL('Sự kiện'!$T$5:$T$304,5),'Sự kiện'!$T$5:$T$304,0),0)=0,"",INDEX('Sự kiện'!$R$5:$R$304,IFERROR(MATCH(SMALL('Sự kiện'!$T$5:$T$304,5),'Sự kiện'!$T$5:$T$304,0),0))&"")
A14: =IF(IFERROR(MATCH(SMALL('Sự kiện'!$T$5:$T$304,6),'Sự kiện'!$T$5:$T$304,0),0)=0,"",INDEX('Sự kiện'!$B$5:$B$304,IFERROR(MATCH(SMALL('Sự kiện'!$T$5:$T$304,6),'Sự kiện'!$T$5:$T$304,0),0))&"") | B14: =IF(IFERROR(MATCH(SMALL('Sự kiện'!$T$5:$T$304,6),'Sự kiện'!$T$5:$T$304,0),0)=0,"",INDEX('Sự kiện'!$C$5:$C$304,IFERROR(MATCH(SMALL('Sự kiện'!$T$5:$T$304,6),'Sự kiện'!$T$5:$T$304,0),0))) | C14: =IF(IFERROR(MATCH(SMALL('Sự kiện'!$T$5:$T$304,6),'Sự kiện'!$T$5:$T$304,0),0)=0,"",INDEX('Sự kiện'!$S$5:$S$304,IFERROR(MATCH(SMALL('Sự kiện'!$T$5:$T$304,6),'Sự kiện'!$T$5:$T$304,0),0))&"") | D14: =IF(IFERROR(MATCH(SMALL('Sự kiện'!$T$5:$T$304,6),'Sự kiện'!$T$5:$T$304,0),0)=0,"",INDEX('Sự kiện'!$K$5:$K$304,IFERROR(MATCH(SMALL('Sự kiện'!$T$5:$T$304,6),'Sự kiện'!$T$5:$T$304,0),0))&"") | E14: =IF(IFERROR(MATCH(SMALL('Sự kiện'!$T$5:$T$304,6),'Sự kiện'!$T$5:$T$304,0),0)=0,"",INDEX('Sự kiện'!$N$5:$N$304,IFERROR(MATCH(SMALL('Sự kiện'!$T$5:$T$304,6),'Sự kiện'!$T$5:$T$304,0),0))) | F14: =IF(A14="","",N(INDEX('Sự kiện'!$M$5:$M$304,IFERROR(MATCH(SMALL('Sự kiện'!$T$5:$T$304,6),'Sự kiện'!$T$5:$T$304,0),0)))-N(E14)-N(G14)) | G14: =IF(IFERROR(MATCH(SMALL('Sự kiện'!$T$5:$T$304,6),'Sự kiện'!$T$5:$T$304,0),0)=0,"",INDEX('Sự kiện'!$O$5:$O$304,IFERROR(MATCH(SMALL('Sự kiện'!$T$5:$T$304,6),'Sự kiện'!$T$5:$T$304,0),0))) | H14: =IF(IFERROR(MATCH(SMALL('Sự kiện'!$T$5:$T$304,6),'Sự kiện'!$T$5:$T$304,0),0)=0,"",INDEX('Sự kiện'!$P$5:$P$304,IFERROR(MATCH(SMALL('Sự kiện'!$T$5:$T$304,6),'Sự kiện'!$T$5:$T$304,0),0))) | I14: =IF(IFERROR(MATCH(SMALL('Sự kiện'!$T$5:$T$304,6),'Sự kiện'!$T$5:$T$304,0),0)=0,"",INDEX('Sự kiện'!$Q$5:$Q$304,IFERROR(MATCH(SMALL('Sự kiện'!$T$5:$T$304,6),'Sự kiện'!$T$5:$T$304,0),0))) | J14: =IF(IFERROR(MATCH(SMALL('Sự kiện'!$T$5:$T$304,6),'Sự kiện'!$T$5:$T$304,0),0)=0,"",INDEX('Sự kiện'!$R$5:$R$304,IFERROR(MATCH(SMALL('Sự kiện'!$T$5:$T$304,6),'Sự kiện'!$T$5:$T$304,0),0))&"")
A15: =IF(IFERROR(MATCH(SMALL('Sự kiện'!$T$5:$T$304,7),'Sự kiện'!$T$5:$T$304,0),0)=0,"",INDEX('Sự kiện'!$B$5:$B$304,IFERROR(MATCH(SMALL('Sự kiện'!$T$5:$T$304,7),'Sự kiện'!$T$5:$T$304,0),0))&"") | B15: =IF(IFERROR(MATCH(SMALL('Sự kiện'!$T$5:$T$304,7),'Sự kiện'!$T$5:$T$304,0),0)=0,"",INDEX('Sự kiện'!$C$5:$C$304,IFERROR(MATCH(SMALL('Sự kiện'!$T$5:$T$304,7),'Sự kiện'!$T$5:$T$304,0),0))) | C15: =IF(IFERROR(MATCH(SMALL('Sự kiện'!$T$5:$T$304,7),'Sự kiện'!$T$5:$T$304,0),0)=0,"",INDEX('Sự kiện'!$S$5:$S$304,IFERROR(MATCH(SMALL('Sự kiện'!$T$5:$T$304,7),'Sự kiện'!$T$5:$T$304,0),0))&"") | D15: =IF(IFERROR(MATCH(SMALL('Sự kiện'!$T$5:$T$304,7),'Sự kiện'!$T$5:$T$304,0),0)=0,"",INDEX('Sự kiện'!$K$5:$K$304,IFERROR(MATCH(SMALL('Sự kiện'!$T$5:$T$304,7),'Sự kiện'!$T$5:$T$304,0),0))&"") | E15: =IF(IFERROR(MATCH(SMALL('Sự kiện'!$T$5:$T$304,7),'Sự kiện'!$T$5:$T$304,0),0)=0,"",INDEX('Sự kiện'!$N$5:$N$304,IFERROR(MATCH(SMALL('Sự kiện'!$T$5:$T$304,7),'Sự kiện'!$T$5:$T$304,0),0))) | F15: =IF(A15="","",N(INDEX('Sự kiện'!$M$5:$M$304,IFERROR(MATCH(SMALL('Sự kiện'!$T$5:$T$304,7),'Sự kiện'!$T$5:$T$304,0),0)))-N(E15)-N(G15)) | G15: =IF(IFERROR(MATCH(SMALL('Sự kiện'!$T$5:$T$304,7),'Sự kiện'!$T$5:$T$304,0),0)=0,"",INDEX('Sự kiện'!$O$5:$O$304,IFERROR(MATCH(SMALL('Sự kiện'!$T$5:$T$304,7),'Sự kiện'!$T$5:$T$304,0),0))) | H15: =IF(IFERROR(MATCH(SMALL('Sự kiện'!$T$5:$T$304,7),'Sự kiện'!$T$5:$T$304,0),0)=0,"",INDEX('Sự kiện'!$P$5:$P$304,IFERROR(MATCH(SMALL('Sự kiện'!$T$5:$T$304,7),'Sự kiện'!$T$5:$T$304,0),0))) | I15: =IF(IFERROR(MATCH(SMALL('Sự kiện'!$T$5:$T$304,7),'Sự kiện'!$T$5:$T$304,0),0)=0,"",INDEX('Sự kiện'!$Q$5:$Q$304,IFERROR(MATCH(SMALL('Sự kiện'!$T$5:$T$304,7),'Sự kiện'!$T$5:$T$304,0),0))) | J15: =IF(IFERROR(MATCH(SMALL('Sự kiện'!$T$5:$T$304,7),'Sự kiện'!$T$5:$T$304,0),0)=0,"",INDEX('Sự kiện'!$R$5:$R$304,IFERROR(MATCH(SMALL('Sự kiện'!$T$5:$T$304,7),'Sự kiện'!$T$5:$T$304,0),0))&"")
A16: =IF(IFERROR(MATCH(SMALL('Sự kiện'!$T$5:$T$304,8),'Sự kiện'!$T$5:$T$304,0),0)=0,"",INDEX('Sự kiện'!$B$5:$B$304,IFERROR(MATCH(SMALL('Sự kiện'!$T$5:$T$304,8),'Sự kiện'!$T$5:$T$304,0),0))&"") | B16: =IF(IFERROR(MATCH(SMALL('Sự kiện'!$T$5:$T$304,8),'Sự kiện'!$T$5:$T$304,0),0)=0,"",INDEX('Sự kiện'!$C$5:$C$304,IFERROR(MATCH(SMALL('Sự kiện'!$T$5:$T$304,8),'Sự kiện'!$T$5:$T$304,0),0))) | C16: =IF(IFERROR(MATCH(SMALL('Sự kiện'!$T$5:$T$304,8),'Sự kiện'!$T$5:$T$304,0),0)=0,"",INDEX('Sự kiện'!$S$5:$S$304,IFERROR(MATCH(SMALL('Sự kiện'!$T$5:$T$304,8),'Sự kiện'!$T$5:$T$304,0),0))&"") | D16: =IF(IFERROR(MATCH(SMALL('Sự kiện'!$T$5:$T$304,8),'Sự kiện'!$T$5:$T$304,0),0)=0,"",INDEX('Sự kiện'!$K$5:$K$304,IFERROR(MATCH(SMALL('Sự kiện'!$T$5:$T$304,8),'Sự kiện'!$T$5:$T$304,0),0))&"") | E16: =IF(IFERROR(MATCH(SMALL('Sự kiện'!$T$5:$T$304,8),'Sự kiện'!$T$5:$T$304,0),0)=0,"",INDEX('Sự kiện'!$N$5:$N$304,IFERROR(MATCH(SMALL('Sự kiện'!$T$5:$T$304,8),'Sự kiện'!$T$5:$T$304,0),0))) | F16: =IF(A16="","",N(INDEX('Sự kiện'!$M$5:$M$304,IFERROR(MATCH(SMALL('Sự kiện'!$T$5:$T$304,8),'Sự kiện'!$T$5:$T$304,0),0)))-N(E16)-N(G16)) | G16: =IF(IFERROR(MATCH(SMALL('Sự kiện'!$T$5:$T$304,8),'Sự kiện'!$T$5:$T$304,0),0)=0,"",INDEX('Sự kiện'!$O$5:$O$304,IFERROR(MATCH(SMALL('Sự kiện'!$T$5:$T$304,8),'Sự kiện'!$T$5:$T$304,0),0))) | H16: =IF(IFERROR(MATCH(SMALL('Sự kiện'!$T$5:$T$304,8),'Sự kiện'!$T$5:$T$304,0),0)=0,"",INDEX('Sự kiện'!$P$5:$P$304,IFERROR(MATCH(SMALL('Sự kiện'!$T$5:$T$304,8),'Sự kiện'!$T$5:$T$304,0),0))) | I16: =IF(IFERROR(MATCH(SMALL('Sự kiện'!$T$5:$T$304,8),'Sự kiện'!$T$5:$T$304,0),0)=0,"",INDEX('Sự kiện'!$Q$5:$Q$304,IFERROR(MATCH(SMALL('Sự kiện'!$T$5:$T$304,8),'Sự kiện'!$T$5:$T$304,0),0))) | J16: =IF(IFERROR(MATCH(SMALL('Sự kiện'!$T$5:$T$304,8),'Sự kiện'!$T$5:$T$304,0),0)=0,"",INDEX('Sự kiện'!$R$5:$R$304,IFERROR(MATCH(SMALL('Sự kiện'!$T$5:$T$304,8),'Sự kiện'!$T$5:$T$304,0),0))&"")
A17: =IF(IFERROR(MATCH(SMALL('Sự kiện'!$T$5:$T$304,9),'Sự kiện'!$T$5:$T$304,0),0)=0,"",INDEX('Sự kiện'!$B$5:$B$304,IFERROR(MATCH(SMALL('Sự kiện'!$T$5:$T$304,9),'Sự kiện'!$T$5:$T$304,0),0))&"") | B17: =IF(IFERROR(MATCH(SMALL('Sự kiện'!$T$5:$T$304,9),'Sự kiện'!$T$5:$T$304,0),0)=0,"",INDEX('Sự kiện'!$C$5:$C$304,IFERROR(MATCH(SMALL('Sự kiện'!$T$5:$T$304,9),'Sự kiện'!$T$5:$T$304,0),0))) | C17: =IF(IFERROR(MATCH(SMALL('Sự kiện'!$T$5:$T$304,9),'Sự kiện'!$T$5:$T$304,0),0)=0,"",INDEX('Sự kiện'!$S$5:$S$304,IFERROR(MATCH(SMALL('Sự kiện'!$T$5:$T$304,9),'Sự kiện'!$T$5:$T$304,0),0))&"") | D17: =IF(IFERROR(MATCH(SMALL('Sự kiện'!$T$5:$T$304,9),'Sự kiện'!$T$5:$T$304,0),0)=0,"",INDEX('Sự kiện'!$K$5:$K$304,IFERROR(MATCH(SMALL('Sự kiện'!$T$5:$T$304,9),'Sự kiện'!$T$5:$T$304,0),0))&"") | E17: =IF(IFERROR(MATCH(SMALL('Sự kiện'!$T$5:$T$304,9),'Sự kiện'!$T$5:$T$304,0),0)=0,"",INDEX('Sự kiện'!$N$5:$N$304,IFERROR(MATCH(SMALL('Sự kiện'!$T$5:$T$304,9),'Sự kiện'!$T$5:$T$304,0),0))) | F17: =IF(A17="","",N(INDEX('Sự kiện'!$M$5:$M$304,IFERROR(MATCH(SMALL('Sự kiện'!$T$5:$T$304,9),'Sự kiện'!$T$5:$T$304,0),0)))-N(E17)-N(G17)) | G17: =IF(IFERROR(MATCH(SMALL('Sự kiện'!$T$5:$T$304,9),'Sự kiện'!$T$5:$T$304,0),0)=0,"",INDEX('Sự kiện'!$O$5:$O$304,IFERROR(MATCH(SMALL('Sự kiện'!$T$5:$T$304,9),'Sự kiện'!$T$5:$T$304,0),0))) | H17: =IF(IFERROR(MATCH(SMALL('Sự kiện'!$T$5:$T$304,9),'Sự kiện'!$T$5:$T$304,0),0)=0,"",INDEX('Sự kiện'!$P$5:$P$304,IFERROR(MATCH(SMALL('Sự kiện'!$T$5:$T$304,9),'Sự kiện'!$T$5:$T$304,0),0))) | I17: =IF(IFERROR(MATCH(SMALL('Sự kiện'!$T$5:$T$304,9),'Sự kiện'!$T$5:$T$304,0),0)=0,"",INDEX('Sự kiện'!$Q$5:$Q$304,IFERROR(MATCH(SMALL('Sự kiện'!$T$5:$T$304,9),'Sự kiện'!$T$5:$T$304,0),0))) | J17: =IF(IFERROR(MATCH(SMALL('Sự kiện'!$T$5:$T$304,9),'Sự kiện'!$T$5:$T$304,0),0)=0,"",INDEX('Sự kiện'!$R$5:$R$304,IFERROR(MATCH(SMALL('Sự kiện'!$T$5:$T$304,9),'Sự kiện'!$T$5:$T$304,0),0))&"")
A18: =IF(IFERROR(MATCH(SMALL('Sự kiện'!$T$5:$T$304,10),'Sự kiện'!$T$5:$T$304,0),0)=0,"",INDEX('Sự kiện'!$B$5:$B$304,IFERROR(MATCH(SMALL('Sự kiện'!$T$5:$T$304,10),'Sự kiện'!$T$5:$T$304,0),0))&"") | B18: =IF(IFERROR(MATCH(SMALL('Sự kiện'!$T$5:$T$304,10),'Sự kiện'!$T$5:$T$304,0),0)=0,"",INDEX('Sự kiện'!$C$5:$C$304,IFERROR(MATCH(SMALL('Sự kiện'!$T$5:$T$304,10),'Sự kiện'!$T$5:$T$304,0),0))) | C18: =IF(IFERROR(MATCH(SMALL('Sự kiện'!$T$5:$T$304,10),'Sự kiện'!$T$5:$T$304,0),0)=0,"",INDEX('Sự kiện'!$S$5:$S$304,IFERROR(MATCH(SMALL('Sự kiện'!$T$5:$T$304,10),'Sự kiện'!$T$5:$T$304,0),0))&"") | D18: =IF(IFERROR(MATCH(SMALL('Sự kiện'!$T$5:$T$304,10),'Sự kiện'!$T$5:$T$304,0),0)=0,"",INDEX('Sự kiện'!$K$5:$K$304,IFERROR(MATCH(SMALL('Sự kiện'!$T$5:$T$304,10),'Sự kiện'!$T$5:$T$304,0),0))&"") | E18: =IF(IFERROR(MATCH(SMALL('Sự kiện'!$T$5:$T$304,10),'Sự kiện'!$T$5:$T$304,0),0)=0,"",INDEX('Sự kiện'!$N$5:$N$304,IFERROR(MATCH(SMALL('Sự kiện'!$T$5:$T$304,10),'Sự kiện'!$T$5:$T$304,0),0))) | F18: =IF(A18="","",N(INDEX('Sự kiện'!$M$5:$M$304,IFERROR(MATCH(SMALL('Sự kiện'!$T$5:$T$304,10),'Sự kiện'!$T$5:$T$304,0),0)))-N(E18)-N(G18)) | G18: =IF(IFERROR(MATCH(SMALL('Sự kiện'!$T$5:$T$304,10),'Sự kiện'!$T$5:$T$304,0),0)=0,"",INDEX('Sự kiện'!$O$5:$O$304,IFERROR(MATCH(SMALL('Sự kiện'!$T$5:$T$304,10),'Sự kiện'!$T$5:$T$304,0),0))) | H18: =IF(IFERROR(MATCH(SMALL('Sự kiện'!$T$5:$T$304,10),'Sự kiện'!$T$5:$T$304,0),0)=0,"",INDEX('Sự kiện'!$P$5:$P$304,IFERROR(MATCH(SMALL('Sự kiện'!$T$5:$T$304,10),'Sự kiện'!$T$5:$T$304,0),0))) | I18: =IF(IFERROR(MATCH(SMALL('Sự kiện'!$T$5:$T$304,10),'Sự kiện'!$T$5:$T$304,0),0)=0,"",INDEX('Sự kiện'!$Q$5:$Q$304,IFERROR(MATCH(SMALL('Sự kiện'!$T$5:$T$304,10),'Sự kiện'!$T$5:$T$304,0),0))) | J18: =IF(IFERROR(MATCH(SMALL('Sự kiện'!$T$5:$T$304,10),'Sự kiện'!$T$5:$T$304,0),0)=0,"",INDEX('Sự kiện'!$R$5:$R$304,IFERROR(MATCH(SMALL('Sự kiện'!$T$5:$T$304,10),'Sự kiện'!$T$5:$T$304,0),0))&"")
A19: =IF(IFERROR(MATCH(SMALL('Sự kiện'!$T$5:$T$304,11),'Sự kiện'!$T$5:$T$304,0),0)=0,"",INDEX('Sự kiện'!$B$5:$B$304,IFERROR(MATCH(SMALL('Sự kiện'!$T$5:$T$304,11),'Sự kiện'!$T$5:$T$304,0),0))&"") | B19: =IF(IFERROR(MATCH(SMALL('Sự kiện'!$T$5:$T$304,11),'Sự kiện'!$T$5:$T$304,0),0)=0,"",INDEX('Sự kiện'!$C$5:$C$304,IFERROR(MATCH(SMALL('Sự kiện'!$T$5:$T$304,11),'Sự kiện'!$T$5:$T$304,0),0))) | C19: =IF(IFERROR(MATCH(SMALL('Sự kiện'!$T$5:$T$304,11),'Sự kiện'!$T$5:$T$304,0),0)=0,"",INDEX('Sự kiện'!$S$5:$S$304,IFERROR(MATCH(SMALL('Sự kiện'!$T$5:$T$304,11),'Sự kiện'!$T$5:$T$304,0),0))&"") | D19: =IF(IFERROR(MATCH(SMALL('Sự kiện'!$T$5:$T$304,11),'Sự kiện'!$T$5:$T$304,0),0)=0,"",INDEX('Sự kiện'!$K$5:$K$304,IFERROR(MATCH(SMALL('Sự kiện'!$T$5:$T$304,11),'Sự kiện'!$T$5:$T$304,0),0))&"") | E19: =IF(IFERROR(MATCH(SMALL('Sự kiện'!$T$5:$T$304,11),'Sự kiện'!$T$5:$T$304,0),0)=0,"",INDEX('Sự kiện'!$N$5:$N$304,IFERROR(MATCH(SMALL('Sự kiện'!$T$5:$T$304,11),'Sự kiện'!$T$5:$T$304,0),0))) | F19: =IF(A19="","",N(INDEX('Sự kiện'!$M$5:$M$304,IFERROR(MATCH(SMALL('Sự kiện'!$T$5:$T$304,11),'Sự kiện'!$T$5:$T$304,0),0)))-N(E19)-N(G19)) | G19: =IF(IFERROR(MATCH(SMALL('Sự kiện'!$T$5:$T$304,11),'Sự kiện'!$T$5:$T$304,0),0)=0,"",INDEX('Sự kiện'!$O$5:$O$304,IFERROR(MATCH(SMALL('Sự kiện'!$T$5:$T$304,11),'Sự kiện'!$T$5:$T$304,0),0))) | H19: =IF(IFERROR(MATCH(SMALL('Sự kiện'!$T$5:$T$304,11),'Sự kiện'!$T$5:$T$304,0),0)=0,"",INDEX('Sự kiện'!$P$5:$P$304,IFERROR(MATCH(SMALL('Sự kiện'!$T$5:$T$304,11),'Sự kiện'!$T$5:$T$304,0),0))) | I19: =IF(IFERROR(MATCH(SMALL('Sự kiện'!$T$5:$T$304,11),'Sự kiện'!$T$5:$T$304,0),0)=0,"",INDEX('Sự kiện'!$Q$5:$Q$304,IFERROR(MATCH(SMALL('Sự kiện'!$T$5:$T$304,11),'Sự kiện'!$T$5:$T$304,0),0))) | J19: =IF(IFERROR(MATCH(SMALL('Sự kiện'!$T$5:$T$304,11),'Sự kiện'!$T$5:$T$304,0),0)=0,"",INDEX('Sự kiện'!$R$5:$R$304,IFERROR(MATCH(SMALL('Sự kiện'!$T$5:$T$304,11),'Sự kiện'!$T$5:$T$304,0),0))&"")
A20: =IF(IFERROR(MATCH(SMALL('Sự kiện'!$T$5:$T$304,12),'Sự kiện'!$T$5:$T$304,0),0)=0,"",INDEX('Sự kiện'!$B$5:$B$304,IFERROR(MATCH(SMALL('Sự kiện'!$T$5:$T$304,12),'Sự kiện'!$T$5:$T$304,0),0))&"") | B20: =IF(IFERROR(MATCH(SMALL('Sự kiện'!$T$5:$T$304,12),'Sự kiện'!$T$5:$T$304,0),0)=0,"",INDEX('Sự kiện'!$C$5:$C$304,IFERROR(MATCH(SMALL('Sự kiện'!$T$5:$T$304,12),'Sự kiện'!$T$5:$T$304,0),0))) | C20: =IF(IFERROR(MATCH(SMALL('Sự kiện'!$T$5:$T$304,12),'Sự kiện'!$T$5:$T$304,0),0)=0,"",INDEX('Sự kiện'!$S$5:$S$304,IFERROR(MATCH(SMALL('Sự kiện'!$T$5:$T$304,12),'Sự kiện'!$T$5:$T$304,0),0))&"") | D20: =IF(IFERROR(MATCH(SMALL('Sự kiện'!$T$5:$T$304,12),'Sự kiện'!$T$5:$T$304,0),0)=0,"",INDEX('Sự kiện'!$K$5:$K$304,IFERROR(MATCH(SMALL('Sự kiện'!$T$5:$T$304,12),'Sự kiện'!$T$5:$T$304,0),0))&"") | E20: =IF(IFERROR(MATCH(SMALL('Sự kiện'!$T$5:$T$304,12),'Sự kiện'!$T$5:$T$304,0),0)=0,"",INDEX('Sự kiện'!$N$5:$N$304,IFERROR(MATCH(SMALL('Sự kiện'!$T$5:$T$304,12),'Sự kiện'!$T$5:$T$304,0),0))) | F20: =IF(A20="","",N(INDEX('Sự kiện'!$M$5:$M$304,IFERROR(MATCH(SMALL('Sự kiện'!$T$5:$T$304,12),'Sự kiện'!$T$5:$T$304,0),0)))-N(E20)-N(G20)) | G20: =IF(IFERROR(MATCH(SMALL('Sự kiện'!$T$5:$T$304,12),'Sự kiện'!$T$5:$T$304,0),0)=0,"",INDEX('Sự kiện'!$O$5:$O$304,IFERROR(MATCH(SMALL('Sự kiện'!$T$5:$T$304,12),'Sự kiện'!$T$5:$T$304,0),0))) | H20: =IF(IFERROR(MATCH(SMALL('Sự kiện'!$T$5:$T$304,12),'Sự kiện'!$T$5:$T$304,0),0)=0,"",INDEX('Sự kiện'!$P$5:$P$304,IFERROR(MATCH(SMALL('Sự kiện'!$T$5:$T$304,12),'Sự kiện'!$T$5:$T$304,0),0))) | I20: =IF(IFERROR(MATCH(SMALL('Sự kiện'!$T$5:$T$304,12),'Sự kiện'!$T$5:$T$304,0),0)=0,"",INDEX('Sự kiện'!$Q$5:$Q$304,IFERROR(MATCH(SMALL('Sự kiện'!$T$5:$T$304,12),'Sự kiện'!$T$5:$T$304,0),0))) | J20: =IF(IFERROR(MATCH(SMALL('Sự kiện'!$T$5:$T$304,12),'Sự kiện'!$T$5:$T$304,0),0)=0,"",INDEX('Sự kiện'!$R$5:$R$304,IFERROR(MATCH(SMALL('Sự kiện'!$T$5:$T$304,12),'Sự kiện'!$T$5:$T$304,0),0))&"")
A22: THEO NGƯỜI PHỤ TRÁCH
A23: Người | B23: Đang mở | C23: Quá hạn | D23: Đến hạn ≤ 3 ngày | E23: Xong | F23: Tổng | G23: % | J23: Tiến độ
A24: =IF('Cài đặt'!$D$5="","",'Cài đặt'!$D$5) | B24: =IF(A24="","",COUNTIFS('Giao việc'!$F$5:$F$3004,A24,'Giao việc'!$R$5:$R$3004,"Có",'Giao việc'!$I$5:$I$3004,"<>Xong",'Giao việc'!$I$5:$I$3004,"<>Bỏ qua")) | C24: =IF(A24="","",COUNTIFS('Giao việc'!$F$5:$F$3004,A24,'Giao việc'!$R$5:$R$3004,"Có",'Giao việc'!$L$5:$L$3004,"*QUÁ HẠN*")) | D24: =IF(A24="","",COUNTIFS('Giao việc'!$F$5:$F$3004,A24,'Giao việc'!$R$5:$R$3004,"Có",'Giao việc'!$L$5:$L$3004,"*Đến hạn*")) | E24: =IF(A24="","",COUNTIFS('Giao việc'!$F$5:$F$3004,A24,'Giao việc'!$R$5:$R$3004,"Có",'Giao việc'!$I$5:$I$3004,"Xong")) | F24: =IF(A24="","",B24+E24) | G24: =IF(OR(A24="",N(F24)=0),"",E24/F24) | J24: =IF(G24="","",REPT("█",ROUND(G24*10,0))&REPT("░",10-ROUND(G24*10,0)))
A25: =IF('Cài đặt'!$D$6="","",'Cài đặt'!$D$6) | B25: =IF(A25="","",COUNTIFS('Giao việc'!$F$5:$F$3004,A25,'Giao việc'!$R$5:$R$3004,"Có",'Giao việc'!$I$5:$I$3004,"<>Xong",'Giao việc'!$I$5:$I$3004,"<>Bỏ qua")) | C25: =IF(A25="","",COUNTIFS('Giao việc'!$F$5:$F$3004,A25,'Giao việc'!$R$5:$R$3004,"Có",'Giao việc'!$L$5:$L$3004,"*QUÁ HẠN*")) | D25: =IF(A25="","",COUNTIFS('Giao việc'!$F$5:$F$3004,A25,'Giao việc'!$R$5:$R$3004,"Có",'Giao việc'!$L$5:$L$3004,"*Đến hạn*")) | E25: =IF(A25="","",COUNTIFS('Giao việc'!$F$5:$F$3004,A25,'Giao việc'!$R$5:$R$3004,"Có",'Giao việc'!$I$5:$I$3004,"Xong")) | F25: =IF(A25="","",B25+E25) | G25: =IF(OR(A25="",N(F25)=0),"",E25/F25) | J25: =IF(G25="","",REPT("█",ROUND(G25*10,0))&REPT("░",10-ROUND(G25*10,0)))
A26: =IF('Cài đặt'!$D$7="","",'Cài đặt'!$D$7) | B26: =IF(A26="","",COUNTIFS('Giao việc'!$F$5:$F$3004,A26,'Giao việc'!$R$5:$R$3004,"Có",'Giao việc'!$I$5:$I$3004,"<>Xong",'Giao việc'!$I$5:$I$3004,"<>Bỏ qua")) | C26: =IF(A26="","",COUNTIFS('Giao việc'!$F$5:$F$3004,A26,'Giao việc'!$R$5:$R$3004,"Có",'Giao việc'!$L$5:$L$3004,"*QUÁ HẠN*")) | D26: =IF(A26="","",COUNTIFS('Giao việc'!$F$5:$F$3004,A26,'Giao việc'!$R$5:$R$3004,"Có",'Giao việc'!$L$5:$L$3004,"*Đến hạn*")) | E26: =IF(A26="","",COUNTIFS('Giao việc'!$F$5:$F$3004,A26,'Giao việc'!$R$5:$R$3004,"Có",'Giao việc'!$I$5:$I$3004,"Xong")) | F26: =IF(A26="","",B26+E26) | G26: =IF(OR(A26="",N(F26)=0),"",E26/F26) | J26: =IF(G26="","",REPT("█",ROUND(G26*10,0))&REPT("░",10-ROUND(G26*10,0)))
A27: =IF('Cài đặt'!$D$8="","",'Cài đặt'!$D$8) | B27: =IF(A27="","",COUNTIFS('Giao việc'!$F$5:$F$3004,A27,'Giao việc'!$R$5:$R$3004,"Có",'Giao việc'!$I$5:$I$3004,"<>Xong",'Giao việc'!$I$5:$I$3004,"<>Bỏ qua")) | C27: =IF(A27="","",COUNTIFS('Giao việc'!$F$5:$F$3004,A27,'Giao việc'!$R$5:$R$3004,"Có",'Giao việc'!$L$5:$L$3004,"*QUÁ HẠN*")) | D27: =IF(A27="","",COUNTIFS('Giao việc'!$F$5:$F$3004,A27,'Giao việc'!$R$5:$R$3004,"Có",'Giao việc'!$L$5:$L$3004,"*Đến hạn*")) | E27: =IF(A27="","",COUNTIFS('Giao việc'!$F$5:$F$3004,A27,'Giao việc'!$R$5:$R$3004,"Có",'Giao việc'!$I$5:$I$3004,"Xong")) | F27: =IF(A27="","",B27+E27) | G27: =IF(OR(A27="",N(F27)=0),"",E27/F27) | J27: =IF(G27="","",REPT("█",ROUND(G27*10,0))&REPT("░",10-ROUND(G27*10,0)))
A28: =IF('Cài đặt'!$D$9="","",'Cài đặt'!$D$9) | B28: =IF(A28="","",COUNTIFS('Giao việc'!$F$5:$F$3004,A28,'Giao việc'!$R$5:$R$3004,"Có",'Giao việc'!$I$5:$I$3004,"<>Xong",'Giao việc'!$I$5:$I$3004,"<>Bỏ qua")) | C28: =IF(A28="","",COUNTIFS('Giao việc'!$F$5:$F$3004,A28,'Giao việc'!$R$5:$R$3004,"Có",'Giao việc'!$L$5:$L$3004,"*QUÁ HẠN*")) | D28: =IF(A28="","",COUNTIFS('Giao việc'!$F$5:$F$3004,A28,'Giao việc'!$R$5:$R$3004,"Có",'Giao việc'!$L$5:$L$3004,"*Đến hạn*")) | E28: =IF(A28="","",COUNTIFS('Giao việc'!$F$5:$F$3004,A28,'Giao việc'!$R$5:$R$3004,"Có",'Giao việc'!$I$5:$I$3004,"Xong")) | F28: =IF(A28="","",B28+E28) | G28: =IF(OR(A28="",N(F28)=0),"",E28/F28) | J28: =IF(G28="","",REPT("█",ROUND(G28*10,0))&REPT("░",10-ROUND(G28*10,0)))
A29: =IF('Cài đặt'!$D$10="","",'Cài đặt'!$D$10) | B29: =IF(A29="","",COUNTIFS('Giao việc'!$F$5:$F$3004,A29,'Giao việc'!$R$5:$R$3004,"Có",'Giao việc'!$I$5:$I$3004,"<>Xong",'Giao việc'!$I$5:$I$3004,"<>Bỏ qua")) | C29: =IF(A29="","",COUNTIFS('Giao việc'!$F$5:$F$3004,A29,'Giao việc'!$R$5:$R$3004,"Có",'Giao việc'!$L$5:$L$3004,"*QUÁ HẠN*")) | D29: =IF(A29="","",COUNTIFS('Giao việc'!$F$5:$F$3004,A29,'Giao việc'!$R$5:$R$3004,"Có",'Giao việc'!$L$5:$L$3004,"*Đến hạn*")) | E29: =IF(A29="","",COUNTIFS('Giao việc'!$F$5:$F$3004,A29,'Giao việc'!$R$5:$R$3004,"Có",'Giao việc'!$I$5:$I$3004,"Xong")) | F29: =IF(A29="","",B29+E29) | G29: =IF(OR(A29="",N(F29)=0),"",E29/F29) | J29: =IF(G29="","",REPT("█",ROUND(G29*10,0))&REPT("░",10-ROUND(G29*10,0)))
A30: =IF('Cài đặt'!$D$11="","",'Cài đặt'!$D$11) | B30: =IF(A30="","",COUNTIFS('Giao việc'!$F$5:$F$3004,A30,'Giao việc'!$R$5:$R$3004,"Có",'Giao việc'!$I$5:$I$3004,"<>Xong",'Giao việc'!$I$5:$I$3004,"<>Bỏ qua")) | C30: =IF(A30="","",COUNTIFS('Giao việc'!$F$5:$F$3004,A30,'Giao việc'!$R$5:$R$3004,"Có",'Giao việc'!$L$5:$L$3004,"*QUÁ HẠN*")) | D30: =IF(A30="","",COUNTIFS('Giao việc'!$F$5:$F$3004,A30,'Giao việc'!$R$5:$R$3004,"Có",'Giao việc'!$L$5:$L$3004,"*Đến hạn*")) | E30: =IF(A30="","",COUNTIFS('Giao việc'!$F$5:$F$3004,A30,'Giao việc'!$R$5:$R$3004,"Có",'Giao việc'!$I$5:$I$3004,"Xong")) | F30: =IF(A30="","",B30+E30) | G30: =IF(OR(A30="",N(F30)=0),"",E30/F30) | J30: =IF(G30="","",REPT("█",ROUND(G30*10,0))&REPT("░",10-ROUND(G30*10,0)))
A31: =IF('Cài đặt'!$D$12="","",'Cài đặt'!$D$12) | B31: =IF(A31="","",COUNTIFS('Giao việc'!$F$5:$F$3004,A31,'Giao việc'!$R$5:$R$3004,"Có",'Giao việc'!$I$5:$I$3004,"<>Xong",'Giao việc'!$I$5:$I$3004,"<>Bỏ qua")) | C31: =IF(A31="","",COUNTIFS('Giao việc'!$F$5:$F$3004,A31,'Giao việc'!$R$5:$R$3004,"Có",'Giao việc'!$L$5:$L$3004,"*QUÁ HẠN*")) | D31: =IF(A31="","",COUNTIFS('Giao việc'!$F$5:$F$3004,A31,'Giao việc'!$R$5:$R$3004,"Có",'Giao việc'!$L$5:$L$3004,"*Đến hạn*")) | E31: =IF(A31="","",COUNTIFS('Giao việc'!$F$5:$F$3004,A31,'Giao việc'!$R$5:$R$3004,"Có",'Giao việc'!$I$5:$I$3004,"Xong")) | F31: =IF(A31="","",B31+E31) | G31: =IF(OR(A31="",N(F31)=0),"",E31/F31) | J31: =IF(G31="","",REPT("█",ROUND(G31*10,0))&REPT("░",10-ROUND(G31*10,0)))
A32: =IF('Cài đặt'!$D$13="","",'Cài đặt'!$D$13) | B32: =IF(A32="","",COUNTIFS('Giao việc'!$F$5:$F$3004,A32,'Giao việc'!$R$5:$R$3004,"Có",'Giao việc'!$I$5:$I$3004,"<>Xong",'Giao việc'!$I$5:$I$3004,"<>Bỏ qua")) | C32: =IF(A32="","",COUNTIFS('Giao việc'!$F$5:$F$3004,A32,'Giao việc'!$R$5:$R$3004,"Có",'Giao việc'!$L$5:$L$3004,"*QUÁ HẠN*")) | D32: =IF(A32="","",COUNTIFS('Giao việc'!$F$5:$F$3004,A32,'Giao việc'!$R$5:$R$3004,"Có",'Giao việc'!$L$5:$L$3004,"*Đến hạn*")) | E32: =IF(A32="","",COUNTIFS('Giao việc'!$F$5:$F$3004,A32,'Giao việc'!$R$5:$R$3004,"Có",'Giao việc'!$I$5:$I$3004,"Xong")) | F32: =IF(A32="","",B32+E32) | G32: =IF(OR(A32="",N(F32)=0),"",E32/F32) | J32: =IF(G32="","",REPT("█",ROUND(G32*10,0))&REPT("░",10-ROUND(G32*10,0)))
A33: =IF('Cài đặt'!$D$14="","",'Cài đặt'!$D$14) | B33: =IF(A33="","",COUNTIFS('Giao việc'!$F$5:$F$3004,A33,'Giao việc'!$R$5:$R$3004,"Có",'Giao việc'!$I$5:$I$3004,"<>Xong",'Giao việc'!$I$5:$I$3004,"<>Bỏ qua")) | C33: =IF(A33="","",COUNTIFS('Giao việc'!$F$5:$F$3004,A33,'Giao việc'!$R$5:$R$3004,"Có",'Giao việc'!$L$5:$L$3004,"*QUÁ HẠN*")) | D33: =IF(A33="","",COUNTIFS('Giao việc'!$F$5:$F$3004,A33,'Giao việc'!$R$5:$R$3004,"Có",'Giao việc'!$L$5:$L$3004,"*Đến hạn*")) | E33: =IF(A33="","",COUNTIFS('Giao việc'!$F$5:$F$3004,A33,'Giao việc'!$R$5:$R$3004,"Có",'Giao việc'!$I$5:$I$3004,"Xong")) | F33: =IF(A33="","",B33+E33) | G33: =IF(OR(A33="",N(F33)=0),"",E33/F33) | J33: =IF(G33="","",REPT("█",ROUND(G33*10,0))&REPT("░",10-ROUND(G33*10,0)))
A34: =IF('Cài đặt'!$D$15="","",'Cài đặt'!$D$15) | B34: =IF(A34="","",COUNTIFS('Giao việc'!$F$5:$F$3004,A34,'Giao việc'!$R$5:$R$3004,"Có",'Giao việc'!$I$5:$I$3004,"<>Xong",'Giao việc'!$I$5:$I$3004,"<>Bỏ qua")) | C34: =IF(A34="","",COUNTIFS('Giao việc'!$F$5:$F$3004,A34,'Giao việc'!$R$5:$R$3004,"Có",'Giao việc'!$L$5:$L$3004,"*QUÁ HẠN*")) | D34: =IF(A34="","",COUNTIFS('Giao việc'!$F$5:$F$3004,A34,'Giao việc'!$R$5:$R$3004,"Có",'Giao việc'!$L$5:$L$3004,"*Đến hạn*")) | E34: =IF(A34="","",COUNTIFS('Giao việc'!$F$5:$F$3004,A34,'Giao việc'!$R$5:$R$3004,"Có",'Giao việc'!$I$5:$I$3004,"Xong")) | F34: =IF(A34="","",B34+E34) | G34: =IF(OR(A34="",N(F34)=0),"",E34/F34) | J34: =IF(G34="","",REPT("█",ROUND(G34*10,0))&REPT("░",10-ROUND(G34*10,0)))
A35: =IF('Cài đặt'!$D$16="","",'Cài đặt'!$D$16) | B35: =IF(A35="","",COUNTIFS('Giao việc'!$F$5:$F$3004,A35,'Giao việc'!$R$5:$R$3004,"Có",'Giao việc'!$I$5:$I$3004,"<>Xong",'Giao việc'!$I$5:$I$3004,"<>Bỏ qua")) | C35: =IF(A35="","",COUNTIFS('Giao việc'!$F$5:$F$3004,A35,'Giao việc'!$R$5:$R$3004,"Có",'Giao việc'!$L$5:$L$3004,"*QUÁ HẠN*")) | D35: =IF(A35="","",COUNTIFS('Giao việc'!$F$5:$F$3004,A35,'Giao việc'!$R$5:$R$3004,"Có",'Giao việc'!$L$5:$L$3004,"*Đến hạn*")) | E35: =IF(A35="","",COUNTIFS('Giao việc'!$F$5:$F$3004,A35,'Giao việc'!$R$5:$R$3004,"Có",'Giao việc'!$I$5:$I$3004,"Xong")) | F35: =IF(A35="","",B35+E35) | G35: =IF(OR(A35="",N(F35)=0),"",E35/F35) | J35: =IF(G35="","",REPT("█",ROUND(G35*10,0))&REPT("░",10-ROUND(G35*10,0)))
A36: =IF('Cài đặt'!$D$17="","",'Cài đặt'!$D$17) | B36: =IF(A36="","",COUNTIFS('Giao việc'!$F$5:$F$3004,A36,'Giao việc'!$R$5:$R$3004,"Có",'Giao việc'!$I$5:$I$3004,"<>Xong",'Giao việc'!$I$5:$I$3004,"<>Bỏ qua")) | C36: =IF(A36="","",COUNTIFS('Giao việc'!$F$5:$F$3004,A36,'Giao việc'!$R$5:$R$3004,"Có",'Giao việc'!$L$5:$L$3004,"*QUÁ HẠN*")) | D36: =IF(A36="","",COUNTIFS('Giao việc'!$F$5:$F$3004,A36,'Giao việc'!$R$5:$R$3004,"Có",'Giao việc'!$L$5:$L$3004,"*Đến hạn*")) | E36: =IF(A36="","",COUNTIFS('Giao việc'!$F$5:$F$3004,A36,'Giao việc'!$R$5:$R$3004,"Có",'Giao việc'!$I$5:$I$3004,"Xong")) | F36: =IF(A36="","",B36+E36) | G36: =IF(OR(A36="",N(F36)=0),"",E36/F36) | J36: =IF(G36="","",REPT("█",ROUND(G36*10,0))&REPT("░",10-ROUND(G36*10,0)))
A37: =IF('Cài đặt'!$D$18="","",'Cài đặt'!$D$18) | B37: =IF(A37="","",COUNTIFS('Giao việc'!$F$5:$F$3004,A37,'Giao việc'!$R$5:$R$3004,"Có",'Giao việc'!$I$5:$I$3004,"<>Xong",'Giao việc'!$I$5:$I$3004,"<>Bỏ qua")) | C37: =IF(A37="","",COUNTIFS('Giao việc'!$F$5:$F$3004,A37,'Giao việc'!$R$5:$R$3004,"Có",'Giao việc'!$L$5:$L$3004,"*QUÁ HẠN*")) | D37: =IF(A37="","",COUNTIFS('Giao việc'!$F$5:$F$3004,A37,'Giao việc'!$R$5:$R$3004,"Có",'Giao việc'!$L$5:$L$3004,"*Đến hạn*")) | E37: =IF(A37="","",COUNTIFS('Giao việc'!$F$5:$F$3004,A37,'Giao việc'!$R$5:$R$3004,"Có",'Giao việc'!$I$5:$I$3004,"Xong")) | F37: =IF(A37="","",B37+E37) | G37: =IF(OR(A37="",N(F37)=0),"",E37/F37) | J37: =IF(G37="","",REPT("█",ROUND(G37*10,0))&REPT("░",10-ROUND(G37*10,0)))
A38: =IF('Cài đặt'!$D$19="","",'Cài đặt'!$D$19) | B38: =IF(A38="","",COUNTIFS('Giao việc'!$F$5:$F$3004,A38,'Giao việc'!$R$5:$R$3004,"Có",'Giao việc'!$I$5:$I$3004,"<>Xong",'Giao việc'!$I$5:$I$3004,"<>Bỏ qua")) | C38: =IF(A38="","",COUNTIFS('Giao việc'!$F$5:$F$3004,A38,'Giao việc'!$R$5:$R$3004,"Có",'Giao việc'!$L$5:$L$3004,"*QUÁ HẠN*")) | D38: =IF(A38="","",COUNTIFS('Giao việc'!$F$5:$F$3004,A38,'Giao việc'!$R$5:$R$3004,"Có",'Giao việc'!$L$5:$L$3004,"*Đến hạn*")) | E38: =IF(A38="","",COUNTIFS('Giao việc'!$F$5:$F$3004,A38,'Giao việc'!$R$5:$R$3004,"Có",'Giao việc'!$I$5:$I$3004,"Xong")) | F38: =IF(A38="","",B38+E38) | G38: =IF(OR(A38="",N(F38)=0),"",E38/F38) | J38: =IF(G38="","",REPT("█",ROUND(G38*10,0))&REPT("░",10-ROUND(G38*10,0)))
A39: Chưa giao người | B39: =COUNTIFS('Giao việc'!$R$5:$R$3004,"Có",'Giao việc'!$L$5:$L$3004,"CHƯA GIAO*")
A41: VIỆC CẦN XỬ LÝ (hạn gần nhất, chưa xong)
A42: Việc | B42: Hạn | C42: Cảnh báo | D42: Người phụ trách | E42: Sự kiện | J42: Trạng thái
A43: =IF(IFERROR(MATCH(SMALL('Giao việc'!$Q$5:$Q$3004,1),'Giao việc'!$Q$5:$Q$3004,0),0)=0,"",INDEX('Giao việc'!$E$5:$E$3004,IFERROR(MATCH(SMALL('Giao việc'!$Q$5:$Q$3004,1),'Giao việc'!$Q$5:$Q$3004,0),0))&"") | B43: =IF(IFERROR(MATCH(SMALL('Giao việc'!$Q$5:$Q$3004,1),'Giao việc'!$Q$5:$Q$3004,0),0)=0,"",INDEX('Giao việc'!$H$5:$H$3004,IFERROR(MATCH(SMALL('Giao việc'!$Q$5:$Q$3004,1),'Giao việc'!$Q$5:$Q$3004,0),0))) | C43: =IF(IFERROR(MATCH(SMALL('Giao việc'!$Q$5:$Q$3004,1),'Giao việc'!$Q$5:$Q$3004,0),0)=0,"",INDEX('Giao việc'!$L$5:$L$3004,IFERROR(MATCH(SMALL('Giao việc'!$Q$5:$Q$3004,1),'Giao việc'!$Q$5:$Q$3004,0),0))&"") | D43: =IF(IFERROR(MATCH(SMALL('Giao việc'!$Q$5:$Q$3004,1),'Giao việc'!$Q$5:$Q$3004,0),0)=0,"",INDEX('Giao việc'!$F$5:$F$3004,IFERROR(MATCH(SMALL('Giao việc'!$Q$5:$Q$3004,1),'Giao việc'!$Q$5:$Q$3004,0),0))&"") | E43: =IF(IFERROR(MATCH(SMALL('Giao việc'!$Q$5:$Q$3004,1),'Giao việc'!$Q$5:$Q$3004,0),0)=0,"",INDEX('Giao việc'!$A$5:$A$3004,IFERROR(MATCH(SMALL('Giao việc'!$Q$5:$Q$3004,1),'Giao việc'!$Q$5:$Q$3004,0),0))&"") | J43: =IF(IFERROR(MATCH(SMALL('Giao việc'!$Q$5:$Q$3004,1),'Giao việc'!$Q$5:$Q$3004,0),0)=0,"",INDEX('Giao việc'!$I$5:$I$3004,IFERROR(MATCH(SMALL('Giao việc'!$Q$5:$Q$3004,1),'Giao việc'!$Q$5:$Q$3004,0),0))&"")
A44: =IF(IFERROR(MATCH(SMALL('Giao việc'!$Q$5:$Q$3004,2),'Giao việc'!$Q$5:$Q$3004,0),0)=0,"",INDEX('Giao việc'!$E$5:$E$3004,IFERROR(MATCH(SMALL('Giao việc'!$Q$5:$Q$3004,2),'Giao việc'!$Q$5:$Q$3004,0),0))&"") | B44: =IF(IFERROR(MATCH(SMALL('Giao việc'!$Q$5:$Q$3004,2),'Giao việc'!$Q$5:$Q$3004,0),0)=0,"",INDEX('Giao việc'!$H$5:$H$3004,IFERROR(MATCH(SMALL('Giao việc'!$Q$5:$Q$3004,2),'Giao việc'!$Q$5:$Q$3004,0),0))) | C44: =IF(IFERROR(MATCH(SMALL('Giao việc'!$Q$5:$Q$3004,2),'Giao việc'!$Q$5:$Q$3004,0),0)=0,"",INDEX('Giao việc'!$L$5:$L$3004,IFERROR(MATCH(SMALL('Giao việc'!$Q$5:$Q$3004,2),'Giao việc'!$Q$5:$Q$3004,0),0))&"") | D44: =IF(IFERROR(MATCH(SMALL('Giao việc'!$Q$5:$Q$3004,2),'Giao việc'!$Q$5:$Q$3004,0),0)=0,"",INDEX('Giao việc'!$F$5:$F$3004,IFERROR(MATCH(SMALL('Giao việc'!$Q$5:$Q$3004,2),'Giao việc'!$Q$5:$Q$3004,0),0))&"") | E44: =IF(IFERROR(MATCH(SMALL('Giao việc'!$Q$5:$Q$3004,2),'Giao việc'!$Q$5:$Q$3004,0),0)=0,"",INDEX('Giao việc'!$A$5:$A$3004,IFERROR(MATCH(SMALL('Giao việc'!$Q$5:$Q$3004,2),'Giao việc'!$Q$5:$Q$3004,0),0))&"") | J44: =IF(IFERROR(MATCH(SMALL('Giao việc'!$Q$5:$Q$3004,2),'Giao việc'!$Q$5:$Q$3004,0),0)=0,"",INDEX('Giao việc'!$I$5:$I$3004,IFERROR(MATCH(SMALL('Giao việc'!$Q$5:$Q$3004,2),'Giao việc'!$Q$5:$Q$3004,0),0))&"")
...

Sheet Giao việc
A1: GIAO VIỆC & THEO DÕI
A2: Mọi việc của mọi sự kiện. OWNER chọn Người phụ trách (cột F, có thể đổi Hạn ở cột H). NGƯỜI PHỤ TRÁCH cập nhật Trạng thái · Ngày xong · Ghi chú. Lọc cột F để xem việc của mình.
A4: Sự kiện | B4: Ngày D | C4: Mốc | D4: Hạng mục | E4: Việc cần làm | F4: Người phụ trách | G4: Phối hợp | H4: Hạn | I4: Trạng thái | J4: Ngày xong | K4: Ghi chú / link | L4: Cảnh báo | M4: _sk | N4: _ma | O4: _n | P4: _t | Q4: _sort | R4: _td
A5: =IF(M5="","",IFERROR(INDEX(SK_B,MATCH(M5,SK_A,0))&"","")) | B5: =IF(M5="","",IFERROR(INDEX(SK_C,MATCH(M5,SK_A,0)),"")) | C5: =IF(O5="","",IF(O5=0,"D",IF(O5<0,"D"&O5,"D+"&O5))) | D5: 1. Kế hoạch | E5: Lập kế hoạch tổng quan (KOL, số khách, mục đích, KPI bán hàng, khuyến mại, khảo sát) + xin Giám đốc duyệt ngân sách | F5: Leader MKT (ví dụ) | G5: Sales, NPP | H5: =IF(OR(B5="",O5=""),"",IF(O5>0,IF(P5="Làm việc",WORKDAY(IFERROR(IF(INDEX(SK_D,MATCH(M5,SK_A,0))="",B5,INDEX(SK_D,MATCH(M5,SK_A,0))),B5),O5,HOLI),IFERROR(IF(INDEX(SK_D,MATCH(M5,SK_A,0))="",B5,INDEX(SK_D,MATCH(M5,SK_A,0))),B5)+O5),B5+O5)) | I5: Xong | J5: 46282 | L5: =IF(E5="","",IF(I5="Bỏ qua","—",IF(I5="Xong",IF(AND(ISNUMBER(J5),ISNUMBER(H5),J5>H5),"Xong trễ","Xong"),IF(F5="","CHƯA GIAO","")&IF(NOT(ISNUMBER(H5)),"",IF(TODAY()>H5,IF(F5=""," · ","")&"QUÁ HẠN "&(TODAY()-H5)&" ngày",IF(H5-TODAY()<=3,IF(F5=""," · ","")&"Đến hạn "&IF(H5=TODAY(),"hôm nay","trong "&(H5-TODAY())&" ngày"),"")))))) | M5: VD-1 | N5: K01 | O5: -30 | P5: Lịch | Q5: =IF(AND(E5<>"",R5="Có",I5<>"Xong",I5<>"Bỏ qua",ISNUMBER(H5)),H5+ROW()/100000,"") | R5: =IF(M5="","",IFERROR(INDEX(SK_L,MATCH(M5,SK_A,0)),""))
A6: =IF(M6="","",IFERROR(INDEX(SK_B,MATCH(M6,SK_A,0))&"","")) | B6: =IF(M6="","",IFERROR(INDEX(SK_C,MATCH(M6,SK_A,0)),"")) | C6: =IF(O6="","",IF(O6=0,"D",IF(O6<0,"D"&O6,"D+"&O6))) | D6: 1. Kế hoạch | E6: Chia việc với NPP, Trường / Viện (tuyển sinh, đồ thực hành, MC, số bàn trưng bày) | F6: Leader MKT (ví dụ) | G6: NPP, Viện | H6: =IF(OR(B6="",O6=""),"",IF(O6>0,IF(P6="Làm việc",WORKDAY(IFERROR(IF(INDEX(SK_D,MATCH(M6,SK_A,0))="",B6,INDEX(SK_D,MATCH(M6,SK_A,0))),B6),O6,HOLI),IFERROR(IF(INDEX(SK_D,MATCH(M6,SK_A,0))="",B6,INDEX(SK_D,MATCH(M6,SK_A,0))),B6)+O6),B6+O6)) | I6: Xong | J6: 46281 | L6: =IF(E6="","",IF(I6="Bỏ qua","—",IF(I6="Xong",IF(AND(ISNUMBER(J6),ISNUMBER(H6),J6>H6),"Xong trễ","Xong"),IF(F6="","CHƯA GIAO","")&IF(NOT(ISNUMBER(H6)),"",IF(TODAY()>H6,IF(F6=""," · ","")&"QUÁ HẠN "&(TODAY()-H6)&" ngày",IF(H6-TODAY()<=3,IF(F6=""," · ","")&"Đến hạn "&IF(H6=TODAY(),"hôm nay","trong "&(H6-TODAY())&" ngày"),"")))))) | M6: VD-1 | N6: K02 | O6: -30 | P6: Lịch | Q6: =IF(AND(E6<>"",R6="Có",I6<>"Xong",I6<>"Bỏ qua",ISNUMBER(H6)),H6+ROW()/100000,"") | R6: =IF(M6="","",IFERROR(INDEX(SK_L,MATCH(M6,SK_A,0)),""))
A7: =IF(M7="","",IFERROR(INDEX(SK_B,MATCH(M7,SK_A,0))&"","")) | B7: =IF(M7="","",IFERROR(INDEX(SK_C,MATCH(M7,SK_A,0)),"")) | C7: =IF(O7="","",IF(O7=0,"D",IF(O7<0,"D"&O7,"D+"&O7))) | D7: 2. KOL & đối tác | E7: Chốt KOL: hợp đồng, lịch di chuyển, xem trước bài giảng, người chăm sóc KOL | F7: Leader MKT (ví dụ) | G7: KOL | H7: =IF(OR(B7="",O7=""),"",IF(O7>0,IF(P7="Làm việc",WORKDAY(IFERROR(IF(INDEX(SK_D,MATCH(M7,SK_A,0))="",B7,INDEX(SK_D,MATCH(M7,SK_A,0))),B7),O7,HOLI),IFERROR(IF(INDEX(SK_D,MATCH(M7,SK_A,0))="",B7,INDEX(SK_D,MATCH(M7,SK_A,0))),B7)+O7),B7+O7)) | I7: Xong | J7: 46283 | L7: =IF(E7="","",IF(I7="Bỏ qua","—",IF(I7="Xong",IF(AND(ISNUMBER(J7),ISNUMBER(H7),J7>H7),"Xong trễ","Xong"),IF(F7="","CHƯA GIAO","")&IF(NOT(ISNUMBER(H7)),"",IF(TODAY()>H7,IF(F7=""," · ","")&"QUÁ HẠN "&(TODAY()-H7)&" ngày",IF(H7-TODAY()<=3,IF(F7=""," · ","")&"Đến hạn "&IF(H7=TODAY(),"hôm nay","trong "&(H7-TODAY())&" ngày"),"")))))) | M7: VD-1 | N7: K03 | O7: -30 | P7: Lịch | Q7: =IF(AND(E7<>"",R7="Có",I7<>"Xong",I7<>"Bỏ qua",ISNUMBER(H7)),H7+ROW()/100000,"") | R7: =IF(M7="","",IFERROR(INDEX(SK_L,MATCH(M7,SK_A,0)),""))
A8: =IF(M8="","",IFERROR(INDEX(SK_B,MATCH(M8,SK_A,0))&"","")) | B8: =IF(M8="","",IFERROR(INDEX(SK_C,MATCH(M8,SK_A,0)),"")) | C8: =IF(O8="","",IF(O8=0,"D",IF(O8<0,"D"&O8,"D+"&O8))) | D8: 3. Tuyển sinh | E8: Mở tuyển sinh: form đăng ký (khảo sát trước, đồng ý dữ liệu, nguồn đăng ký) + nhóm Zalo khách | F8: Digital (ví dụ) | G8: Sales, NPP | H8: =IF(OR(B8="",O8=""),"",IF(O8>0,IF(P8="Làm việc",WORKDAY(IFERROR(IF(INDEX(SK_D,MATCH(M8,SK_A,0))="",B8,INDEX(SK_D,MATCH(M8,SK_A,0))),B8),O8,HOLI),IFERROR(IF(INDEX(SK_D,MATCH(M8,SK_A,0))="",B8,INDEX(SK_D,MATCH(M8,SK_A,0))),B8)+O8),B8+O8)) | I8: Xong | J8: 46280 | L8: =IF(E8="","",IF(I8="Bỏ qua","—",IF(I8="Xong",IF(AND(ISNUMBER(J8),ISNUMBER(H8),J8>H8),"Xong trễ","Xong"),IF(F8="","CHƯA GIAO","")&IF(NOT(ISNUMBER(H8)),"",IF(TODAY()>H8,IF(F8=""," · ","")&"QUÁ HẠN "&(TODAY()-H8)&" ngày",IF(H8-TODAY()<=3,IF(F8=""," · ","")&"Đến hạn "&IF(H8=TODAY(),"hôm nay","trong "&(H8-TODAY())&" ngày"),"")))))) | M8: VD-1 | N8: K04 | O8: -30 | P8: Lịch | Q8: =IF(AND(E8<>"",R8="Có",I8<>"Xong",I8<>"Bỏ qua",ISNUMBER(H8)),H8+ROW()/100000,"") | R8: =IF(M8="","",IFERROR(INDEX(SK_L,MATCH(M8,SK_A,0)),""))
A9: =IF(M9="","",IFERROR(INDEX(SK_B,MATCH(M9,SK_A,0))&"","")) | B9: =IF(M9="","",IFERROR(INDEX(SK_C,MATCH(M9,SK_A,0)),"")) | C9: =IF(O9="","",IF(O9=0,"D",IF(O9<0,"D"&O9,"D+"&O9))) | D9: 3. Tuyển sinh | E9: Báo cáo số đăng ký theo nguồn cho team (thứ Hai hằng tuần, đến D-1) | F9: Leader MKT (ví dụ) | G9: Sales, NPP | H9: =IF(OR(B9="",O9=""),"",IF(O9>0,IF(P9="Làm việc",WORKDAY(IFERROR(IF(INDEX(SK_D,MATCH(M9,SK_A,0))="",B9,INDEX(SK_D,MATCH(M9,SK_A,0))),B9),O9,HOLI),IFERROR(IF(INDEX(SK_D,MATCH(M9,SK_A,0))="",B9,INDEX(SK_D,MATCH(M9,SK_A,0))),B9)+O9),B9+O9)) | I9: Xong | J9: 46309 | L9: =IF(E9="","",IF(I9="Bỏ qua","—",IF(I9="Xong",IF(AND(ISNUMBER(J9),ISNUMBER(H9),J9>H9),"Xong trễ","Xong"),IF(F9="","CHƯA GIAO","")&IF(NOT(ISNUMBER(H9)),"",IF(TODAY()>H9,IF(F9=""," · ","")&"QUÁ HẠN "&(TODAY()-H9)&" ngày",IF(H9-TODAY()<=3,IF(F9=""," · ","")&"Đến hạn "&IF(H9=TODAY(),"hôm nay","trong "&(H9-TODAY())&" ngày"),"")))))) | M9: VD-1 | N9: K05 | O9: -1 | P9: Lịch | Q9: =IF(AND(E9<>"",R9="Có",I9<>"Xong",I9<>"Bỏ qua",ISNUMBER(H9)),H9+ROW()/100000,"") | R9: =IF(M9="","",IFERROR(INDEX(SK_L,MATCH(M9,SK_A,0)),""))
A10: =IF(M10="","",IFERROR(INDEX(SK_B,MATCH(M10,SK_A,0))&"","")) | B10: =IF(M10="","",IFERROR(INDEX(SK_C,MATCH(M10,SK_A,0)),"")) | C10: =IF(O10="","",IF(O10=0,"D",IF(O10<0,"D"&O10,"D+"&O10))) | D10: 3. Tuyển sinh | E10: Checkpoint D-14: đăng ký < 60% target ⇒ báo Giám đốc phương án | F10: Leader MKT (ví dụ) | G10: Giám đốc | H10: =IF(OR(B10="",O10=""),"",IF(O10>0,IF(P10="Làm việc",WORKDAY(IFERROR(IF(INDEX(SK_D,MATCH(M10,SK_A,0))="",B10,INDEX(SK_D,MATCH(M10,SK_A,0))),B10),O10,HOLI),IFERROR(IF(INDEX(SK_D,MATCH(M10,SK_A,0))="",B10,INDEX(SK_D,MATCH(M10,SK_A,0))),B10)+O10),B10+O10)) | I10: Xong | J10: 46298 | L10: =IF(E10="","",IF(I10="Bỏ qua","—",IF(I10="Xong",IF(AND(ISNUMBER(J10),ISNUMBER(H10),J10>H10),"Xong trễ","Xong"),IF(F10="","CHƯA GIAO","")&IF(NOT(ISNUMBER(H10)),"",IF(TODAY()>H10,IF(F10=""," · ","")&"QUÁ HẠN "&(TODAY()-H10)&" ngày",IF(H10-TODAY()<=3,IF(F10=""," · ","")&"Đến hạn "&IF(H10=TODAY(),"hôm nay","trong "&(H10-TODAY())&" ngày"),"")))))) | M10: VD-1 | N10: K06 | O10: -14 | P10: Lịch | Q10: =IF(AND(E10<>"",R10="Có",I10<>"Xong",I10<>"Bỏ qua",ISNUMBER(H10)),H10+ROW()/100000,"") | R10: =IF(M10="","",IFERROR(INDEX(SK_L,MATCH(M10,SK_A,0)),""))
A11: =IF(M11="","",IFERROR(INDEX(SK_B,MATCH(M11,SK_A,0))&"","")) | B11: =IF(M11="","",IFERROR(INDEX(SK_C,MATCH(M11,SK_A,0)),"")) | C11: =IF(O11="","",IF(O11=0,"D",IF(O11<0,"D"&O11,"D+"&O11))) | D11: 3. Tuyển sinh | E11: Sales / NPP gửi đủ thông tin khách đăng ký hộ (Họ tên · SĐT · Nơi công tác) | F11: Sales Dental (ví dụ) | G11: NPP | H11: =IF(OR(B11="",O11=""),"",IF(O11>0,IF(P11="Làm việc",WORKDAY(IFERROR(IF(INDEX(SK_D,MATCH(M11,SK_A,0))="",B11,INDEX(SK_D,MATCH(M11,SK_A,0))),B11),O11,HOLI),IFERROR(IF(INDEX(SK_D,MATCH(M11,SK_A,0))="",B11,INDEX(SK_D,MATCH(M11,SK_A,0))),B11)+O11),B11+O11)) | I11: Xong | J11: 46307 | L11: =IF(E11="","",IF(I11="Bỏ qua","—",IF(I11="Xong",IF(AND(ISNUMBER(J11),ISNUMBER(H11),J11>H11),"Xong trễ","Xong"),IF(F11="","CHƯA GIAO","")&IF(NOT(ISNUMBER(H11)),"",IF(TODAY()>H11,IF(F11=""," · ","")&"QUÁ HẠN "&(TODAY()-H11)&" ngày",IF(H11-TODAY()<=3,IF(F11=""," · ","")&"Đến hạn "&IF(H11=TODAY(),"hôm nay","trong "&(H11-TODAY())&" ngày"),"")))))) | M11: VD-1 | N11: K07 | O11: -5 | P11: Lịch | Q11: =IF(AND(E11<>"",R11="Có",I11<>"Xong",I11<>"Bỏ qua",ISNUMBER(H11)),H11+ROW()/100000,"") | R11: =IF(M11="","",IFERROR(INDEX(SK_L,MATCH(M11,SK_A,0)),""))
A12: =IF(M12="","",IFERROR(INDEX(SK_B,MATCH(M12,SK_A,0))&"","")) | B12: =IF(M12="","",IFERROR(INDEX(SK_C,MATCH(M12,SK_A,0)),"")) | C12: =IF(O12="","",IF(O12=0,"D",IF(O12<0,"D"&O12,"D+"&O12))) | D12: 4. Truyền thông | E12: Đăng chuỗi bài truyền thông sự kiện | F12: Digital (ví dụ) | G12: Sales, NPP chia sẻ | H12: =IF(OR(B12="",O12=""),"",IF(O12>0,IF(P12="Làm việc",WORKDAY(IFERROR(IF(INDEX(SK_D,MATCH(M12,SK_A,0))="",B12,INDEX(SK_D,MATCH(M12,SK_A,0))),B12),O12,HOLI),IFERROR(IF(INDEX(SK_D,MATCH(M12,SK_A,0))="",B12,INDEX(SK_D,MATCH(M12,SK_A,0))),B12)+O12),B12+O12)) | I12: Xong | J12: 46298 | L12: =IF(E12="","",IF(I12="Bỏ qua","—",IF(I12="Xong",IF(AND(ISNUMBER(J12),ISNUMBER(H12),J12>H12),"Xong trễ","Xong"),IF(F12="","CHƯA GIAO","")&IF(NOT(ISNUMBER(H12)),"",IF(TODAY()>H12,IF(F12=""," · ","")&"QUÁ HẠN "&(TODAY()-H12)&" ngày",IF(H12-TODAY()<=3,IF(F12=""," · ","")&"Đến hạn "&IF(H12=TODAY(),"hôm nay","trong "&(H12-TODAY())&" ngày"),"")))))) | M12: VD-1 | N12: K08 | O12: -14 | P12: Lịch | Q12: =IF(AND(E12<>"",R12="Có",I12<>"Xong",I12<>"Bỏ qua",ISNUMBER(H12)),H12+ROW()/100000,"") | R12: =IF(M12="","",IFERROR(INDEX(SK_L,MATCH(M12,SK_A,0)),""))
A13: =IF(M13="","",IFERROR(INDEX(SK_B,MATCH(M13,SK_A,0))&"","")) | B13: =IF(M13="","",IFERROR(INDEX(SK_C,MATCH(M13,SK_A,0)),"")) | C13: =IF(O13="","",IF(O13=0,"D",IF(O13<0,"D"&O13,"D+"&O13))) | D13: 5. Địa điểm & hậu cần | E13: Đặt địa điểm (ngày, phòng, sức chứa, báo giá) | F13: Trade (ví dụ) | G13: Địa điểm | H13: =IF(OR(B13="",O13=""),"",IF(O13>0,IF(P13="Làm việc",WORKDAY(IFERROR(IF(INDEX(SK_D,MATCH(M13,SK_A,0))="",B13,INDEX(SK_D,MATCH(M13,SK_A,0))),B13),O13,HOLI),IFERROR(IF(INDEX(SK_D,MATCH(M13,SK_A,0))="",B13,INDEX(SK_D,MATCH(M13,SK_A,0))),B13)+O13),B13+O13)) | I13: Xong | J13: 46283 | L13: =IF(E13="","",IF(I13="Bỏ qua","—",IF(I13="Xong",IF(AND(ISNUMBER(J13),ISNUMBER(H13),J13>H13),"Xong trễ","Xong"),IF(F13="","CHƯA GIAO","")&IF(NOT(ISNUMBER(H13)),"",IF(TODAY()>H13,IF(F13=""," · ","")&"QUÁ HẠN "&(TODAY()-H13)&" ngày",IF(H13-TODAY()<=3,IF(F13=""," · ","")&"Đến hạn "&IF(H13=TODAY(),"hôm nay","trong "&(H13-TODAY())&" ngày"),"")))))) | M13: VD-1 | N13: K09 | O13: -30 | P13: Lịch | Q13: =IF(AND(E13<>"",R13="Có",I13<>"Xong",I13<>"Bỏ qua",ISNUMBER(H13)),H13+ROW()/100000,"") | R13: =IF(M13="","",IFERROR(INDEX(SK_L,MATCH(M13,SK_A,0)),""))
A14: =IF(M14="","",IFERROR(INDEX(SK_B,MATCH(M14,SK_A,0))&"","")) | B14: =IF(M14="","",IFERROR(INDEX(SK_C,MATCH(M14,SK_A,0)),"")) | C14: =IF(O14="","",IF(O14=0,"D",IF(O14<0,"D"&O14,"D+"&O14))) | D14: 5. Địa điểm & hậu cần | E14: Chốt setup với địa điểm: sơ đồ, tea break / ăn trưa, kỹ thuật, sự kiện khác cùng giờ | F14: Trade (ví dụ) | G14: Địa điểm | H14: =IF(OR(B14="",O14=""),"",IF(O14>0,IF(P14="Làm việc",WORKDAY(IFERROR(IF(INDEX(SK_D,MATCH(M14,SK_A,0))="",B14,INDEX(SK_D,MATCH(M14,SK_A,0))),B14),O14,HOLI),IFERROR(IF(INDEX(SK_D,MATCH(M14,SK_A,0))="",B14,INDEX(SK_D,MATCH(M14,SK_A,0))),B14)+O14),B14+O14)) | I14: Xong | J14: 46298 | L14: =IF(E14="","",IF(I14="Bỏ qua","—",IF(I14="Xong",IF(AND(ISNUMBER(J14),ISNUMBER(H14),J14>H14),"Xong trễ","Xong"),IF(F14="","CHƯA GIAO","")&IF(NOT(ISNUMBER(H14)),"",IF(TODAY()>H14,IF(F14=""," · ","")&"QUÁ HẠN "&(TODAY()-H14)&" ngày",IF(H14-TODAY()<=3,IF(F14=""," · ","")&"Đến hạn "&IF(H14=TODAY(),"hôm nay","trong "&(H14-TODAY())&" ngày"),"")))))) | M14: VD-1 | N14: K10 | O14: -14 | P14: Lịch | Q14: =IF(AND(E14<>"",R14="Có",I14<>"Xong",I14<>"Bỏ qua",ISNUMBER(H14)),H14+ROW()/100000,"") | R14: =IF(M14="","",IFERROR(INDEX(SK_L,MATCH(M14,SK_A,0)),""))
A15: =IF(M15="","",IFERROR(INDEX(SK_B,MATCH(M15,SK_A,0))&"","")) | B15: =IF(M15="","",IFERROR(INDEX(SK_C,MATCH(M15,SK_A,0)),"")) | C15: =IF(O15="","",IF(O15=0,"D",IF(O15<0,"D"&O15,"D+"&O15))) | D15: 6. Nội dung | E15: Timeline chi tiết ngày D | F15: Leader MKT (ví dụ) | G15: KOL, Viện | H15: =IF(OR(B15="",O15=""),"",IF(O15>0,IF(P15="Làm việc",WORKDAY(IFERROR(IF(INDEX(SK_D,MATCH(M15,SK_A,0))="",B15,INDEX(SK_D,MATCH(M15,SK_A,0))),B15),O15,HOLI),IFERROR(IF(INDEX(SK_D,MATCH(M15,SK_A,0))="",B15,INDEX(SK_D,MATCH(M15,SK_A,0))),B15)+O15),B15+O15)) | I15: Xong | J15: 46305 | L15: =IF(E15="","",IF(I15="Bỏ qua","—",IF(I15="Xong",IF(AND(ISNUMBER(J15),ISNUMBER(H15),J15>H15),"Xong trễ","Xong"),IF(F15="","CHƯA GIAO","")&IF(NOT(ISNUMBER(H15)),"",IF(TODAY()>H15,IF(F15=""," · ","")&"QUÁ HẠN "&(TODAY()-H15)&" ngày",IF(H15-TODAY()<=3,IF(F15=""," · ","")&"Đến hạn "&IF(H15=TODAY(),"hôm nay","trong "&(H15-TODAY())&" ngày"),"")))))) | M15: VD-1 | N15: K12 | O15: -7 | P15: Lịch | Q15: =IF(AND(E15<>"",R15="Có",I15<>"Xong",I15<>"Bỏ qua",ISNUMBER(H15)),H15+ROW()/100000,"") | R15: =IF(M15="","",IFERROR(INDEX(SK_L,MATCH(M15,SK_A,0)),""))
A16: =IF(M16="","",IFERROR(INDEX(SK_B,MATCH(M16,SK_A,0))&"","")) | B16: =IF(M16="","",IFERROR(INDEX(SK_C,MATCH(M16,SK_A,0)),"")) | C16: =IF(O16="","",IF(O16=0,"D",IF(O16<0,"D"&O16,"D+"&O16))) | D16: 6. Nội dung | E16: Kịch bản MC, kịch bản phát biểu, video trình chiếu | F16: Digital (ví dụ) | G16: KOL, Viện | H16: =IF(OR(B16="",O16=""),"",IF(O16>0,IF(P16="Làm việc",WORKDAY(IFERROR(IF(INDEX(SK_D,MATCH(M16,SK_A,0))="",B16,INDEX(SK_D,MATCH(M16,SK_A,0))),B16),O16,HOLI),IFERROR(IF(INDEX(SK_D,MATCH(M16,SK_A,0))="",B16,INDEX(SK_D,MATCH(M16,SK_A,0))),B16)+O16),B16+O16)) | I16: Xong | J16: 46305 | L16: =IF(E16="","",IF(I16="Bỏ qua","—",IF(I16="Xong",IF(AND(ISNUMBER(J16),ISNUMBER(H16),J16>H16),"Xong trễ","Xong"),IF(F16="","CHƯA GIAO","")&IF(NOT(ISNUMBER(H16)),"",IF(TODAY()>H16,IF(F16=""," · ","")&"QUÁ HẠN "&(TODAY()-H16)&" ngày",IF(H16-TODAY()<=3,IF(F16=""," · ","")&"Đến hạn "&IF(H16=TODAY(),"hôm nay","trong "&(H16-TODAY())&" ngày"),"")))))) | M16: VD-1 | N16: K13 | O16: -7 | P16: Lịch | Q16: =IF(AND(E16<>"",R16="Có",I16<>"Xong",I16<>"Bỏ qua",ISNUMBER(H16)),H16+ROW()/100000,"") | R16: =IF(M16="","",IFERROR(INDEX(SK_L,MATCH(M16,SK_A,0)),""))
... A26: =IF(M26="","",IFERROR(INDEX(SK_B,MATCH(M26,SK_A,0))&"","")) | B26: =IF(M26="","",IFERROR(INDEX(SK_C,MATCH(M26,SK_A,0)),"")) | C26: =IF(O26="","",IF(O26=0,"D",IF(O26<0,"D"&O26,"D+"&O26))) | D26: 9. Ngày D | E26: Bán hàng tại bàn trưng bày + ghi khách quan tâm | F26: Sales Dental (ví dụ) | G26: NPP | H26: =IF(OR(B26="",O26=""),"",IF(O26>0,IF(P26="Làm việc",WORKDAY(IFERROR(IF(INDEX(SK_D,MATCH(M26,SK_A,0))="",B26,INDEX(SK_D,MATCH(M26,SK_A,0))),B26),O26,HOLI),IFERROR(IF(INDEX(SK_D,MATCH(M26,SK_A,0))="",B26,INDEX(SK_D,MATCH(M26,SK_A,0))),B26)+O26),B26+O26)) | I26: Xong | J26: 46312 | L26: =IF(E26="","",IF(I26="Bỏ qua","—",IF(I26="Xong",IF(AND(ISNUMBER(J26),ISNUMBER(H26),J26>H26),"Xong trễ","Xong"),IF(F26="","CHƯA GIAO","")&IF(NOT(ISNUMBER(H26)),"",IF(TODAY()>H26,IF(F26=""," · ","")&"QUÁ HẠN "&(TODAY()-H26)&" ngày",IF(H26-TODAY()<=3,IF(F26=""," · ","")&"Đến hạn "&IF(H26=TODAY(),"hôm nay","trong "&(H26-TODAY())&" ngày"),"")))))) | M26: VD-1 | N26: K24 | O26: 0 | P26: Lịch | Q26: =IF(AND(E26<>"",R26="Có",I26<>"Xong",I26<>"Bỏ qua",ISNUMBER(H26)),H26+ROW()/100000,"") | R26: =IF(M26="","",IFERROR(INDEX(SK_L,MATCH(M26,SK_A,0)),""))
A27: =IF(M27="","",IFERROR(INDEX(SK_B,MATCH(M27,SK_A,0))&"","")) | B27: =IF(M27="","",IFERROR(INDEX(SK_C,MATCH(M27,SK_A,0)),"")) | C27: =IF(O27="","",IF(O27=0,"D",IF(O27<0,"D"&O27,"D+"&O27))) | D27: 9. Ngày D | E27: Thu dọn, kiểm đếm, ghi POSM hỏng | F27: Trade (ví dụ) | G27: NPP | H27: =IF(OR(B27="",O27=""),"",IF(O27>0,IF(P27="Làm việc",WORKDAY(IFERROR(IF(INDEX(SK_D,MATCH(M27,SK_A,0))="",B27,INDEX(SK_D,MATCH(M27,SK_A,0))),B27),O27,HOLI),IFERROR(IF(INDEX(SK_D,MATCH(M27,SK_A,0))="",B27,INDEX(SK_D,MATCH(M27,SK_A,0))),B27)+O27),B27+O27)) | I27: Chưa làm | L27: =IF(E27="","",IF(I27="Bỏ qua","—",IF(I27="Xong",IF(AND(ISNUMBER(J27),ISNUMBER(H27),J27>H27),"Xong trễ","Xong"),IF(F27="","CHƯA GIAO","")&IF(NOT(ISNUMBER(H27)),"",IF(TODAY()>H27,IF(F27=""," · ","")&"QUÁ HẠN "&(TODAY()-H27)&" ngày",IF(H27-TODAY()<=3,IF(F27=""," · ","")&"Đến hạn "&IF(H27=TODAY(),"hôm nay","trong "&(H27-TODAY())&" ngày"),"")))))) | M27: VD-1 | N27: K25 | O27: 0 | P27: Lịch | Q27: =IF(AND(E27<>"",R27="Có",I27<>"Xong",I27<>"Bỏ qua",ISNUMBER(H27)),H27+ROW()/100000,"") | R27: =IF(M27="","",IFERROR(INDEX(SK_L,MATCH(M27,SK_A,0)),""))
A28: =IF(M28="","",IFERROR(INDEX(SK_B,MATCH(M28,SK_A,0))&"","")) | B28: =IF(M28="","",IFERROR(INDEX(SK_C,MATCH(M28,SK_A,0)),"")) | C28: =IF(O28="","",IF(O28=0,"D",IF(O28<0,"D"&O28,"D+"&O28))) | D28: 10. Sau sự kiện | E28: Bài cảm ơn + ảnh recap; video recap (nếu có) | F28: Digital (ví dụ) | H28: =IF(OR(B28="",O28=""),"",IF(O28>0,IF(P28="Làm việc",WORKDAY(IFERROR(IF(INDEX(SK_D,MATCH(M28,SK_A,0))="",B28,INDEX(SK_D,MATCH(M28,SK_A,0))),B28),O28,HOLI),IFERROR(IF(INDEX(SK_D,MATCH(M28,SK_A,0))="",B28,INDEX(SK_D,MATCH(M28,SK_A,0))),B28)+O28),B28+O28)) | I28: Xong | J28: 46314 | L28: =IF(E28="","",IF(I28="Bỏ qua","—",IF(I28="Xong",IF(AND(ISNUMBER(J28),ISNUMBER(H28),J28>H28),"Xong trễ","Xong"),IF(F28="","CHƯA GIAO","")&IF(NOT(ISNUMBER(H28)),"",IF(TODAY()>H28,IF(F28=""," · ","")&"QUÁ HẠN "&(TODAY()-H28)&" ngày",IF(H28-TODAY()<=3,IF(F28=""," · ","")&"Đến hạn "&IF(H28=TODAY(),"hôm nay","trong "&(H28-TODAY())&" ngày"),"")))))) | M28: VD-1 | N28: K26 | O28: 2 | P28: Làm việc | Q28: =IF(AND(E28<>"",R28="Có",I28<>"Xong",I28<>"Bỏ qua",ISNUMBER(H28)),H28+ROW()/100000,"") | R28: =IF(M28="","",IFERROR(INDEX(SK_L,MATCH(M28,SK_A,0)),""))
A29: =IF(M29="","",IFERROR(INDEX(SK_B,MATCH(M29,SK_A,0))&"","")) | B29: =IF(M29="","",IFERROR(INDEX(SK_C,MATCH(M29,SK_A,0)),"")) | C29: =IF(O29="","",IF(O29=0,"D",IF(O29<0,"D"&O29,"D+"&O29))) | D29: 10. Sau sự kiện | E29: Scan biểu mẫu ký tay + upload ảnh / video lên folder sự kiện | F29: Trade (ví dụ) | G29: Digital MKT | H29: =IF(OR(B29="",O29=""),"",IF(O29>0,IF(P29="Làm việc",WORKDAY(IFERROR(IF(INDEX(SK_D,MATCH(M29,SK_A,0))="",B29,INDEX(SK_D,MATCH(M29,SK_A,0))),B29),O29,HOLI),IFERROR(IF(INDEX(SK_D,MATCH(M29,SK_A,0))="",B29,INDEX(SK_D,MATCH(M29,SK_A,0))),B29)+O29),B29+O29)) | I29: Xong | J29: 46313 | L29: =IF(E29="","",IF(I29="Bỏ qua","—",IF(I29="Xong",IF(AND(ISNUMBER(J29),ISNUMBER(H29),J29>H29),"Xong trễ","Xong"),IF(F29="","CHƯA GIAO","")&IF(NOT(ISNUMBER(H29)),"",IF(TODAY()>H29,IF(F29=""," · ","")&"QUÁ HẠN "&(TODAY()-H29)&" ngày",IF(H29-TODAY()<=3,IF(F29=""," · ","")&"Đến hạn "&IF(H29=TODAY(),"hôm nay","trong "&(H29-TODAY())&" ngày"),"")))))) | M29: VD-1 | N29: K27 | O29: 2 | P29: Làm việc | Q29: =IF(AND(E29<>"",R29="Có",I29<>"Xong",I29<>"Bỏ qua",ISNUMBER(H29)),H29+ROW()/100000,"") | R29: =IF(M29="","",IFERROR(INDEX(SK_L,MATCH(M29,SK_A,0)),""))
A30: =IF(M30="","",IFERROR(INDEX(SK_B,MATCH(M30,SK_A,0))&"","")) | B30: =IF(M30="","",IFERROR(INDEX(SK_C,MATCH(M30,SK_A,0)),"")) | C30: =IF(O30="","",IF(O30=0,"D",IF(O30<0,"D"&O30,"D+"&O30))) | D30: 10. Sau sự kiện | E30: Đối chiếu dữ liệu khách (loại trùng, đủ trường) ⇒ CUSTOMER LIST; tổng hợp khảo sát | F30: Digital (ví dụ) | G30: Sales, NPP | H30: =IF(OR(B30="",O30=""),"",IF(O30>0,IF(P30="Làm việc",WORKDAY(IFERROR(IF(INDEX(SK_D,MATCH(M30,SK_A,0))="",B30,INDEX(SK_D,MATCH(M30,SK_A,0))),B30),O30,HOLI),IFERROR(IF(INDEX(SK_D,MATCH(M30,SK_A,0))="",B30,INDEX(SK_D,MATCH(M30,SK_A,0))),B30)+O30),B30+O30)) | I30: Xong | J30: 46316 | L30: =IF(E30="","",IF(I30="Bỏ qua","—",IF(I30="Xong",IF(AND(ISNUMBER(J30),ISNUMBER(H30),J30>H30),"Xong trễ","Xong"),IF(F30="","CHƯA GIAO","")&IF(NOT(ISNUMBER(H30)),"",IF(TODAY()>H30,IF(F30=""," · ","")&"QUÁ HẠN "&(TODAY()-H30)&" ngày",IF(H30-TODAY()<=3,IF(F30=""," · ","")&"Đến hạn "&IF(H30=TODAY(),"hôm nay","trong "&(H30-TODAY())&" ngày"),"")))))) | M30: VD-1 | N30: K28 | O30: 3 | P30: Làm việc | Q30: =IF(AND(E30<>"",R30="Có",I30<>"Xong",I30<>"Bỏ qua",ISNUMBER(H30)),H30+ROW()/100000,"") | R30: =IF(M30="","",IFERROR(INDEX(SK_L,MATCH(M30,SK_A,0)),""))
A31: =IF(M31="","",IFERROR(INDEX(SK_B,MATCH(M31,SK_A,0))&"","")) | B31: =IF(M31="","",IFERROR(INDEX(SK_C,MATCH(M31,SK_A,0)),"")) | C31: =IF(O31="","",IF(O31=0,"D",IF(O31<0,"D"&O31,"D+"&O31))) | D31: 10. Sau sự kiện | E31: Sales + NPP gửi số liệu bán hàng tại sự kiện | F31: Sales Dental (ví dụ) | G31: NPP | H31: =IF(OR(B31="",O31=""),"",IF(O31>0,IF(P31="Làm việc",WORKDAY(IFERROR(IF(INDEX(SK_D,MATCH(M31,SK_A,0))="",B31,INDEX(SK_D,MATCH(M31,SK_A,0))),B31),O31,HOLI),IFERROR(IF(INDEX(SK_D,MATCH(M31,SK_A,0))="",B31,INDEX(SK_D,MATCH(M31,SK_A,0))),B31)+O31),B31+O31)) | I31: Chưa làm | L31: =IF(E31="","",IF(I31="Bỏ qua","—",IF(I31="Xong",IF(AND(ISNUMBER(J31),ISNUMBER(H31),J31>H31),"Xong trễ","Xong"),IF(F31="","CHƯA GIAO","")&IF(NOT(ISNUMBER(H31)),"",IF(TODAY()>H31,IF(F31=""," · ","")&"QUÁ HẠN "&(TODAY()-H31)&" ngày",IF(H31-TODAY()<=3,IF(F31=""," · ","")&"Đến hạn "&IF(H31=TODAY(),"hôm nay","trong "&(H31-TODAY())&" ngày"),"")))))) | M31: VD-1 | N31: K29 | O31: 3 | P31: Làm việc | Q31: =IF(AND(E31<>"",R31="Có",I31<>"Xong",I31<>"Bỏ qua",ISNUMBER(H31)),H31+ROW()/100000,"") | R31: =IF(M31="","",IFERROR(INDEX(SK_L,MATCH(M31,SK_A,0)),""))
